Workbook

Sheet 【AI】予想・答え合わせ
A1: ■ AI予想・答え合わせ検証シート
A3: 日付 (結果日) | B3: 機種名 | C3: 台番号 | D3: 予想・狙い根拠 | E3: 翌日G数 | F3: 翌日差枚 | G3: 翌日設定スコア | H3: 判定 (○/×)
A4: 46197 | B4: マイジャグラーV | C4: 755 | D4: テスト(昨日マイナス→本日プラス) | E4: =IF(OR(A4="",C4=""),"",SUMIFS(【データ】蓄積用!$D$2:$D$15000,【データ】蓄積用!$A$2:$A$15000,A4,【データ】蓄積用!$C$2:$C$15000,C4)) -> 1649 | F4: =IF(OR(A4="",C4=""),"",SUMIFS(【データ】蓄積用!$E$2:$E$15000,【データ】蓄積用!$A$2:$A$15000,A4,【データ】蓄積用!$C$2:$C$15000,C4)) -> 1243 | G4: =IF(OR(A4="",C4=""),"",SUMIFS(【データ】蓄積用!$L$2:$L$15000,【データ】蓄積用!$A$2:$A$15000,A4,【データ】蓄積用!$C$2:$C$15000,C4)) -> 1.2513 | H4: =IF(A4="", "", IF(OR(E4="", E4="集計"), "", IF(ISNUMBER(SEARCH("ジャグラー", B4)), IF(IFERROR(VALUE(G4), 0)>=4, "〇", "×"), IF(IFERROR(VALUE(F4), 0)>=1000, "〇", "×")))) -> ×
A5: 46198 | B5: マイジャグラーV | C5: 522 | D5: 前日単発凹み・内部数値優秀 スコア193.4と突出。浅い凹みからの反発＆設定上げ狙いの大本命。 | E5: =IF(OR(A5="",C5=""),"",SUMIFS(【データ】蓄積用!$D$2:$D$15000,【データ】蓄積用!$A$2:$A$15000,A5,【データ】蓄積用!$C$2:$C$15000,C5)) -> 6603 | F5: =IF(OR(A5="",C5=""),"",SUMIFS(【データ】蓄積用!$E$2:$E$15000,【データ】蓄積用!$A$2:$A$15000,A5,【データ】蓄積用!$C$2:$C$15000,C5)) -> -1046 | G5: =IF(OR(A5="",C5=""),"",SUMIFS(【データ】蓄積用!$L$2:$L$15000,【データ】蓄積用!$A$2:$A$15000,A5,【データ】蓄積用!$C$2:$C$15000,C5)) -> 0.9472 | H5: =IF(A5="", "", IF(OR(E5="", E5="集計"), "", IF(ISNUMBER(SEARCH("ジャグラー", B5)), IF(IFERROR(VALUE(G5), 0)>=4, "〇", "×"), IF(IFERROR(VALUE(F5), 0)>=1000, "〇", "×")))) -> ×
A6: 46198 | B6: マイジャグラーV | C6: 515 | D6: 前日凹みからの上げ狙い 522番台が取れなかった場合のセカンドチョイス。 | E6: =IF(OR(A6="",C6=""),"",SUMIFS(【データ】蓄積用!$D$2:$D$15000,【データ】蓄積用!$A$2:$A$15000,A6,【データ】蓄積用!$C$2:$C$15000,C6)) -> 3299 | F6: =IF(OR(A6="",C6=""),"",SUMIFS(【データ】蓄積用!$E$2:$E$15000,【データ】蓄積用!$A$2:$A$15000,A6,【データ】蓄積用!$C$2:$C$15000,C6)) -> -247 | G6: =IF(OR(A6="",C6=""),"",SUMIFS(【データ】蓄積用!$L$2:$L$15000,【データ】蓄積用!$A$2:$A$15000,A6,【データ】蓄積用!$C$2:$C$15000,C6)) -> 0.975 | H6: =IF(A6="", "", IF(OR(E6="", E6="集計"), "", IF(ISNUMBER(SEARCH("ジャグラー", B6)), IF(IFERROR(VALUE(G6), 0)>=4, "〇", "×"), IF(IFERROR(VALUE(F6), 0)>=1000, "〇", "×")))) -> ×
A7: 46198 | B7: マイジャグラーV | C7: 512 | D7: 前日凹みからの上げ狙い マイジャグ島全体に上げの傾向があるか見極めるための試金石。 | E7: =IF(OR(A7="",C7=""),"",SUMIFS(【データ】蓄積用!$D$2:$D$15000,【データ】蓄積用!$A$2:$A$15000,A7,【データ】蓄積用!$C$2:$C$15000,C7)) -> 6488 | F7: =IF(OR(A7="",C7=""),"",SUMIFS(【データ】蓄積用!$E$2:$E$15000,【データ】蓄積用!$A$2:$A$15000,A7,【データ】蓄積用!$C$2:$C$15000,C7)) -> 1723 | G7: =IF(OR(A7="",C7=""),"",SUMIFS(【データ】蓄積用!$L$2:$L$15000,【データ】蓄積用!$A$2:$A$15000,A7,【データ】蓄積用!$C$2:$C$15000,C7)) -> 1.0885 | H7: =IF(A7="", "", IF(OR(E7="", E7="集計"), "", IF(ISNUMBER(SEARCH("ジャグラー", B7)), IF(IFERROR(VALUE(G7), 0)>=4, "〇", "×"), IF(IFERROR(VALUE(F7), 0)>=1000, "〇", "×")))) -> ×
A8: 46198 | B8: ゴーゴージャグラー3 | C8: 502 | D8: 前日凹みからの上げ狙い スコア84.2。マイジャグに座れなかった際のリカバリー候補。 | E8: =IF(OR(A8="",C8=""),"",SUMIFS(【データ】蓄積用!$D$2:$D$15000,【データ】蓄積用!$A$2:$A$15000,A8,【データ】蓄積用!$C$2:$C$15000,C8)) -> 5248 | F8: =IF(OR(A8="",C8=""),"",SUMIFS(【データ】蓄積用!$E$2:$E$15000,【データ】蓄積用!$A$2:$A$15000,A8,【データ】蓄積用!$C$2:$C$15000,C8)) -> -802 | G8: =IF(OR(A8="",C8=""),"",SUMIFS(【データ】蓄積用!$L$2:$L$15000,【データ】蓄積用!$A$2:$A$15000,A8,【データ】蓄積用!$C$2:$C$15000,C8)) -> 0.9491 | H8: =IF(A8="", "", IF(OR(E8="", E8="集計"), "", IF(ISNUMBER(SEARCH("ジャグラー", B8)), IF(IFERROR(VALUE(G8), 0)>=4, "〇", "×"), IF(IFERROR(VALUE(F8), 0)>=1000, "〇", "×")))) -> ×
A9: 46198 | B9: ネオアイムジャグラーEX | C9: 553 | D9: 高設定の据え置き狙い 前日差枚-74枚。展開負けした高設定の据え置きに期待。 | E9: =IF(OR(A9="",C9=""),"",SUMIFS(【データ】蓄積用!$D$2:$D$15000,【データ】蓄積用!$A$2:$A$15000,A9,【データ】蓄積用!$C$2:$C$15000,C9)) -> 731 | F9: =IF(OR(A9="",C9=""),"",SUMIFS(【データ】蓄積用!$E$2:$E$15000,【データ】蓄積用!$A$2:$A$15000,A9,【データ】蓄積用!$C$2:$C$15000,C9)) -> -729 | G9: =IF(OR(A9="",C9=""),"",SUMIFS(【データ】蓄積用!$L$2:$L$15000,【データ】蓄積用!$A$2:$A$15000,A9,【データ】蓄積用!$C$2:$C$15000,C9)) -> 0.6676 | H9: =IF(A9="", "", IF(OR(E9="", E9="集計"), "", IF(ISNUMBER(SEARCH("ジャグラー", B9)), IF(IFERROR(VALUE(G9), 0)>=4, "〇", "×"), IF(IFERROR(VALUE(F9), 0)>=1000, "〇", "×")))) -> ×
A10: 46198 | B10: 甲鉄城のカバネリ 海門決戦 | C10: 757 | D10: スコア異常値・リセット恩恵 スコア310の圧倒的期待値。朝イチ最優先で狙うべき特大チャンス台。 | E10: =IF(OR(A10="",C10=""),"",SUMIFS(【データ】蓄積用!$D$2:$D$15000,【データ】蓄積用!$A$2:$A$15000,A10,【データ】蓄積用!$C$2:$C$15000,C10)) -> 1182 | F10: =IF(OR(A10="",C10=""),"",SUMIFS(【データ】蓄積用!$E$2:$E$15000,【データ】蓄積用!$A$2:$A$15000,A10,【データ】蓄積用!$C$2:$C$15000,C10)) -> -1190 | G10: =IF(OR(A10="",C10=""),"",SUMIFS(【データ】蓄積用!$L$2:$L$15000,【データ】蓄積用!$A$2:$A$15000,A10,【データ】蓄積用!$C$2:$C$15000,C10)) -> 0.6644 | H10: =IF(A10="", "", IF(OR(E10="", E10="集計"), "", IF(ISNUMBER(SEARCH("ジャグラー", B10)), IF(IFERROR(VALUE(G10), 0)>=4, "〇", "×"), IF(IFERROR(VALUE(F10), 0)>=1000, "〇", "×")))) -> ×
A11: 46198 | B11: モンキーターンV | C11: 681 | D11: プラマイゼロからの波狙い 前日-8枚。スコア171.5と高く、リセット後のモード移行等に期待。 | E11: =IF(OR(A11="",C11=""),"",SUMIFS(【データ】蓄積用!$D$2:$D$15000,【データ】蓄積用!$A$2:$A$15000,A11,【データ】蓄積用!$C$2:$C$15000,C11)) -> 985 | F11: =IF(OR(A11="",C11=""),"",SUMIFS(【データ】蓄積用!$E$2:$E$15000,【データ】蓄積用!$A$2:$A$15000,A11,【データ】蓄積用!$C$2:$C$15000,C11)) -> 1844 | G11: =IF(OR(A11="",C11=""),"",SUMIFS(【データ】蓄積用!$L$2:$L$15000,【データ】蓄積用!$A$2:$A$15000,A11,【データ】蓄積用!$C$2:$C$15000,C11)) -> 1.624 | H11: =IF(A11="", "", IF(OR(E11="", E11="集計"), "", IF(ISNUMBER(SEARCH("ジャグラー", B11)), IF(IFERROR(VALUE(G11), 0)>=4, "〇", "×"), IF(IFERROR(VALUE(F11), 0)>=1000, "〇", "×")))) -> 〇
A12: 46198 | B12: 戦国乙女5 業火を穿つ宿焔の双刃 | C12: 672 | D12: 特大凹みからの反発狙い 前日-4656枚。ハイリスクハイリターン。連続凹み台なら回避推奨。 | E12: =IF(OR(A12="",C12=""),"",SUMIFS(【データ】蓄積用!$D$2:$D$15000,【データ】蓄積用!$A$2:$A$15000,A12,【データ】蓄積用!$C$2:$C$15000,C12)) -> 3804 | F12: =IF(OR(A12="",C12=""),"",SUMIFS(【データ】蓄積用!$E$2:$E$15000,【データ】蓄積用!$A$2:$A$15000,A12,【データ】蓄積用!$C$2:$C$15000,C12)) -> -247 | G12: =IF(OR(A12="",C12=""),"",SUMIFS(【データ】蓄積用!$L$2:$L$15000,【データ】蓄積用!$A$2:$A$15000,A12,【データ】蓄積用!$C$2:$C$15000,C12)) -> 0.9784 | H12: =IF(A12="", "", IF(OR(E12="", E12="集計"), "", IF(ISNUMBER(SEARCH("ジャグラー", B12)), IF(IFERROR(VALUE(G12), 0)>=4, "〇", "×"), IF(IFERROR(VALUE(F12), 0)>=1000, "〇", "×")))) -> ×
A13: 46198 | B13: ミリオンゴッド‐神々の軌跡‐ | C13: 633 | D13: 前日凹みからの上げ狙い スコア147.6。ゴッド特有のリセット恩恵やモード狙いが視野に入るか。 | E13: =IF(OR(A13="",C13=""),"",SUMIFS(【データ】蓄積用!$D$2:$D$15000,【データ】蓄積用!$A$2:$A$15000,A13,【データ】蓄積用!$C$2:$C$15000,C13)) -> 3214 | F13: =IF(OR(A13="",C13=""),"",SUMIFS(【データ】蓄積用!$E$2:$E$15000,【データ】蓄積用!$A$2:$A$15000,A13,【データ】蓄積用!$C$2:$C$15000,C13)) -> 2765 | G13: =IF(OR(A13="",C13=""),"",SUMIFS(【データ】蓄積用!$L$2:$L$15000,【データ】蓄積用!$A$2:$A$15000,A13,【データ】蓄積用!$C$2:$C$15000,C13)) -> 1.2868 | H13: =IF(A13="", "", IF(OR(E13="", E13="集計"), "", IF(ISNUMBER(SEARCH("ジャグラー", B13)), IF(IFERROR(VALUE(G13), 0)>=4, "〇", "×"), IF(IFERROR(VALUE(F13), 0)>=1000, "〇", "×")))) -> 〇
A14: 46198 | B14: スーパーリオエース2 | C14: 725 | D14: 前日凹みからの反発狙い スコア144.4。他の主力機種が取れなかった際のサブ候補としてキープ。 | E14: =IF(OR(A14="",C14=""),"",SUMIFS(【データ】蓄積用!$D$2:$D$15000,【データ】蓄積用!$A$2:$A$15000,A14,【データ】蓄積用!$C$2:$C$15000,C14)) -> 3842 | F14: =IF(OR(A14="",C14=""),"",SUMIFS(【データ】蓄積用!$E$2:$E$15000,【データ】蓄積用!$A$2:$A$15000,A14,【データ】蓄積用!$C$2:$C$15000,C14)) -> 1686 | G14: =IF(OR(A14="",C14=""),"",SUMIFS(【データ】蓄積用!$L$2:$L$15000,【データ】蓄積用!$A$2:$A$15000,A14,【データ】蓄積用!$C$2:$C$15000,C14)) -> 1.1463 | H14: =IF(A14="", "", IF(OR(E14="", E14="集計"), "", IF(ISNUMBER(SEARCH("ジャグラー", B14)), IF(IFERROR(VALUE(G14), 0)>=4, "〇", "×"), IF(IFERROR(VALUE(F14), 0)>=1000, "〇", "×")))) -> 〇
A15: 46199 | B15: マイジャグラーV | C15: 522 | D15: 前日大本命で不発だったものの、6のつく日の特日で店側がリベンジ設定を投入する本命台として再チャレンジ。 | E15: =IF(OR(A15="",C15=""),"",SUMIFS(【データ】蓄積用!$D$2:$D$15000,【データ】蓄積用!$A$2:$A$15000,A15,【データ】蓄積用!$C$2:$C$15000,C15)) -> 6708 | F15: =IF(OR(A15="",C15=""),"",SUMIFS(【データ】蓄積用!$E$2:$E$15000,【データ】蓄積用!$A$2:$A$15000,A15,【データ】蓄積用!$C$2:$C$15000,C15)) -> -223 | G15: =IF(OR(A15="",C15=""),"",SUMIFS(【データ】蓄積用!$L$2:$L$15000,【データ】蓄積用!$A$2:$A$15000,A15,【データ】蓄積用!$C$2:$C$15000,C15)) -> 0.9889 | H15: =IF(A15="", "", IF(OR(E15="", E15="集計"), "", IF(ISNUMBER(SEARCH("ジャグラー", B15)), IF(IFERROR(VALUE(G15), 0)>=4, "〇", "×"), IF(IFERROR(VALUE(F15), 0)>=1000, "〇", "×")))) -> ×
... A84: 46205 | B84: 東京喰種 | C84: 710 | D84: 前日-1,799枚。メイン機種以外への設定散らし・ズラしのクセを考慮し、サブ機種からのV字回復を狙うリスクヘッジ。 | E84: =IF(OR(A84="",C84=""),"",SUMIFS(【データ】蓄積用!$D$2:$D$15000,【データ】蓄積用!$A$2:$A$15000,A84,【データ】蓄積用!$C$2:$C$15000,C84)) -> 1279 | F84: =IF(OR(A84="",C84=""),"",SUMIFS(【データ】蓄積用!$E$2:$E$15000,【データ】蓄積用!$A$2:$A$15000,A84,【データ】蓄積用!$C$2:$C$15000,C84)) -> -1603 | G84: =IF(OR(A84="",C84=""),"",SUMIFS(【データ】蓄積用!$L$2:$L$15000,【データ】蓄積用!$A$2:$A$15000,A84,【データ】蓄積用!$C$2:$C$15000,C84)) -> 0.5822 | H84: =IF(A84="", "", IF(OR(E84="", E84="集計"), "", IF(ISNUMBER(SEARCH("ジャグラー", B84)), IF(IFERROR(VALUE(G84), 0)>=4, "〇", "×"), IF(IFERROR(VALUE(F84), 0)>=1000, "〇", "×")))) -> ×

Sheet 【分析】高設定履歴DB
A1: 高設定履歴データベース（全期間全データ集積・特定日＆曜日分析対応）
A2: ⚙️ 特定日末尾設定 (変更可): | B2: 7 | C2: 3 | D2: 5 | E2: ゾロ目
A3: 特定日判定 (自動) | B3: =IF(B5="","", IF(OR(AND($B$2<>"", RIGHT(DAY(B5), 1)=TEXT($B$2, "0")), AND($C$2<>"", RIGHT(DAY(B5), 1)=TEXT($C$2, "0")), AND($D$2<>"", RIGHT(DAY(B5), 1)=TEXT($D$2, "0")), AND($E$2="ゾロ目", DAY(B5)=11), AND($E$2="ゾロ目", DAY(B5)=22)), "★特定日", "通常日")) -> 通常日 | C3: =IF(C5="","", IF(OR(AND($B$2<>"", RIGHT(DAY(C5), 1)=TEXT($B$2, "0")), AND($C$2<>"", RIGHT(DAY(C5), 1)=TEXT($C$2, "0")), AND($D$2<>"", RIGHT(DAY(C5), 1)=TEXT($D$2, "0")), AND($E$2="ゾロ目", DAY(C5)=11), AND($E$2="ゾロ目", DAY(C5)=22)), "★特定日", "通常日")) -> 通常日 | D3: =IF(D5="","", IF(OR(AND($B$2<>"", RIGHT(DAY(D5), 1)=TEXT($B$2, "0")), AND($C$2<>"", RIGHT(DAY(D5), 1)=TEXT($C$2, "0")), AND($D$2<>"", RIGHT(DAY(D5), 1)=TEXT($D$2, "0")), AND($E$2="ゾロ目", DAY(D5)=11), AND($E$2="ゾロ目", DAY(D5)=22)), "★特定日", "通常日")) -> 通常日 | E3: =IF(E5="","", IF(OR(AND($B$2<>"", RIGHT(DAY(E5), 1)=TEXT($B$2, "0")), AND($C$2<>"", RIGHT(DAY(E5), 1)=TEXT($C$2, "0")), AND($D$2<>"", RIGHT(DAY(E5), 1)=TEXT($D$2, "0")), AND($E$2="ゾロ目", DAY(E5)=11), AND($E$2="ゾロ目", DAY(E5)=22)), "★特定日", "通常日")) -> 通常日 | F3: =IF(F5="","", IF(OR(AND($B$2<>"", RIGHT(DAY(F5), 1)=TEXT($B$2, "0")), AND($C$2<>"", RIGHT(DAY(F5), 1)=TEXT($C$2, "0")), AND($D$2<>"", RIGHT(DAY(F5), 1)=TEXT($D$2, "0")), AND($E$2="ゾロ目", DAY(F5)=11), AND($E$2="ゾロ目", DAY(F5)=22)), "★特定日", "通常日")) -> 通常日 | G3: =IF(G5="","", IF(OR(AND($B$2<>"", RIGHT(DAY(G5), 1)=TEXT($B$2, "0")), AND($C$2<>"", RIGHT(DAY(G5), 1)=TEXT($C$2, "0")), AND($D$2<>"", RIGHT(DAY(G5), 1)=TEXT($D$2, "0")), AND($E$2="ゾロ目", DAY(G5)=11), AND($E$2="ゾロ目", DAY(G5)=22)), "★特定日", "通常日")) -> ★特定日 | H3: =IF(H5="","", IF(OR(AND($B$2<>"", RIGHT(DAY(H5), 1)=TEXT($B$2, "0")), AND($C$2<>"", RIGHT(DAY(H5), 1)=TEXT($C$2, "0")), AND($D$2<>"", RIGHT(DAY(H5), 1)=TEXT($D$2, "0")), AND($E$2="ゾロ目", DAY(H5)=11), AND($E$2="ゾロ目", DAY(H5)=22)), "★特定日", "通常日")) -> 通常日 | I3: =IF(I5="","", IF(OR(AND($B$2<>"", RIGHT(DAY(I5), 1)=TEXT($B$2, "0")), AND($C$2<>"", RIGHT(DAY(I5), 1)=TEXT($C$2, "0")), AND($D$2<>"", RIGHT(DAY(I5), 1)=TEXT($D$2, "0")), AND($E$2="ゾロ目", DAY(I5)=11), AND($E$2="ゾロ目", DAY(I5)=22)), "★特定日", "通常日")) -> ★特定日 | ... BG3: =IF(BG5="","", IF(OR(AND($B$2<>"", RIGHT(DAY(BG5), 1)=TEXT($B$2, "0")), AND($C$2<>"", RIGHT(DAY(BG5), 1)=TEXT($C$2, "0")), AND($D$2<>"", RIGHT(DAY(BG5), 1)=TEXT($D$2, "0")), AND($E$2="ゾロ目", DAY(BG5)=11), AND($E$2="ゾロ目", DAY(BG5)=22)), "★特定日", "通常日"))
A4: 曜日 | B4: =IF(B5="","", TEXT(B5, "aaa")) -> 金 | C4: =IF(C5="","", TEXT(C5, "aaa")) -> 土 | D4: =IF(D5="","", TEXT(D5, "aaa")) -> 日 | E4: =IF(E5="","", TEXT(E5, "aaa")) -> 月 | F4: =IF(F5="","", TEXT(F5, "aaa")) -> 火 | G4: =IF(G5="","", TEXT(G5, "aaa")) -> 水 | H4: =IF(H5="","", TEXT(H5, "aaa")) -> 木 | I4: =IF(I5="","", TEXT(I5, "aaa")) -> 金 | ... BG4: =IF(BG5="","", TEXT(BG5, "aaa"))
A5: 日付 (過去全期間) | B5: 46171 | C5: 46172 | D5: 46173 | E5: 46174 | F5: 46175 | G5: 46176 | H5: 46177 | I5: 46178 | J5: 46179 | K5: 46180 | L5: 46181 | M5: 46182 | N5: 46183 | O5: 46184 | P5: 46185 | Q5: 46186 | R5: 46187 | S5: 46188 | T5: 46189 | U5: 46190 | V5: 46191 | W5: 46192 | X5: 46193 | Y5: 46194 | Z5: 46195 | AA5: 46196 | AB5: 46197 | AC5: 46198 | AD5: 46199 | AE5: 46200 | AF5: 46201 | AG5: 46202 | AH5: 46203 | AI5: 46204 | AJ5: 46205 | AK5: 46206 | AL5: 46207 | AM5: 46208 | AN5: 46209 | AO5: 46210 | AP5: 46211 | AQ5: 46212 | AR5: 46213 | AS5: 46214 | AT5: 46215 | AU5: 46216 | AV5: 46217 | AW5: 46218 | AX5: 46219
A6: 台番号 / 日付
A7: 501 | B7: =IF(OR($A7="", B$5=""), "", IF(COUNTIFS(【データ】蓄積用!A$2:A$10000, B$5, 【データ】蓄積用!C$2:C$10000, $A7, 【データ】蓄積用!D$2:D$10000, ">=3000", 【データ】蓄積用!E$2:E$10000, ">=1500")>0, "〇", IF(COUNTIFS(【データ】蓄積用!A$2:A$10000, B$5, 【データ】蓄積用!C$2:C$10000, $A7, 【データ】蓄積用!Q$2:Q$10000, 1, 【データ】蓄積用!AC$2:AC$10000, ">=4.0")>0, "〇", "×"))) -> × | C7: =IF(OR($A7="", C$5=""), "", IF(COUNTIFS(【データ】蓄積用!A$2:A$10000, C$5, 【データ】蓄積用!C$2:C$10000, $A7, 【データ】蓄積用!D$2:D$10000, ">=3000", 【データ】蓄積用!E$2:E$10000, ">=1500")>0, "〇", IF(COUNTIFS(【データ】蓄積用!A$2:A$10000, C$5, 【データ】蓄積用!C$2:C$10000, $A7, 【データ】蓄積用!Q$2:Q$10000, 1, 【データ】蓄積用!AC$2:AC$10000, ">=4.0")>0, "〇", "×"))) -> × | D7: =IF(OR($A7="", D$5=""), "", IF(COUNTIFS(【データ】蓄積用!A$2:A$10000, D$5, 【データ】蓄積用!C$2:C$10000, $A7, 【データ】蓄積用!D$2:D$10000, ">=3000", 【データ】蓄積用!E$2:E$10000, ">=1500")>0, "〇", IF(COUNTIFS(【データ】蓄積用!A$2:A$10000, D$5, 【データ】蓄積用!C$2:C$10000, $A7, 【データ】蓄積用!Q$2:Q$10000, 1, 【データ】蓄積用!AC$2:AC$10000, ">=4.0")>0, "〇", "×"))) -> × | E7: =IF(OR($A7="", E$5=""), "", IF(COUNTIFS(【データ】蓄積用!A$2:A$10000, E$5, 【データ】蓄積用!C$2:C$10000, $A7, 【データ】蓄積用!D$2:D$10000, ">=3000", 【データ】蓄積用!E$2:E$10000, ">=1500")>0, "〇", IF(COUNTIFS(【データ】蓄積用!A$2:A$10000, E$5, 【データ】蓄積用!C$2:C$10000, $A7, 【データ】蓄積用!Q$2:Q$10000, 1, 【データ】蓄積用!AC$2:AC$10000, ">=4.0")>0, "〇", "×"))) -> × | F7: =IF(OR($A7="", F$5=""), "", IF(COUNTIFS(【データ】蓄積用!A$2:A$10000, F$5, 【データ】蓄積用!C$2:C$10000, $A7, 【データ】蓄積用!D$2:D$10000, ">=3000", 【データ】蓄積用!E$2:E$10000, ">=1500")>0, "〇", IF(COUNTIFS(【データ】蓄積用!A$2:A$10000, F$5, 【データ】蓄積用!C$2:C$10000, $A7, 【データ】蓄積用!Q$2:Q$10000, 1, 【データ】蓄積用!AC$2:AC$10000, ">=4.0")>0, "〇", "×"))) -> × | G7: =IF(OR($A7="", G$5=""), "", IF(COUNTIFS(【データ】蓄積用!A$2:A$10000, G$5, 【データ】蓄積用!C$2:C$10000, $A7, 【データ】蓄積用!D$2:D$10000, ">=3000", 【データ】蓄積用!E$2:E$10000, ">=1500")>0, "〇", IF(COUNTIFS(【データ】蓄積用!A$2:A$10000, G$5, 【データ】蓄積用!C$2:C$10000, $A7, 【データ】蓄積用!Q$2:Q$10000, 1, 【データ】蓄積用!AC$2:AC$10000, ">=4.0")>0, "〇", "×"))) -> × | H7: =IF(OR($A7="", H$5=""), "", IF(COUNTIFS(【データ】蓄積用!A$2:A$10000, H$5, 【データ】蓄積用!C$2:C$10000, $A7, 【データ】蓄積用!D$2:D$10000, ">=3000", 【データ】蓄積用!E$2:E$10000, ">=1500")>0, "〇", IF(COUNTIFS(【データ】蓄積用!A$2:A$10000, H$5, 【データ】蓄積用!C$2:C$10000, $A7, 【データ】蓄積用!Q$2:Q$10000, 1, 【データ】蓄積用!AC$2:AC$10000, ">=4.0")>0, "〇", "×"))) -> × | I7: =IF(OR($A7="", I$5=""), "", IF(COUNTIFS(【データ】蓄積用!A$2:A$10000, I$5, 【データ】蓄積用!C$2:C$10000, $A7, 【データ】蓄積用!D$2:D$10000, ">=3000", 【データ】蓄積用!E$2:E$10000, ">=1500")>0, "〇", IF(COUNTIFS(【データ】蓄積用!A$2:A$10000, I$5, 【データ】蓄積用!C$2:C$10000, $A7, 【データ】蓄積用!Q$2:Q$10000, 1, 【データ】蓄積用!AC$2:AC$10000, ">=4.0")>0, "〇", "×"))) -> × | J7: =IF(OR($A7="", J$5=""), "", IF(COUNTIFS(【データ】蓄積用!A$2:A$10000, J$5, 【データ】蓄積用!C$2:C$10000, $A7, 【データ】蓄積用!D$2:D$10000, ">=3000", 【データ】蓄積用!E$2:E$10000, ">=1500")>0, "〇", IF(COUNTIFS(【データ】蓄積用!A$2:A$10000, J$5, 【データ】蓄積用!C$2:C$10000, $A7, 【データ】蓄積用!Q$2:Q$10000, 1, 【データ】蓄積用!AC$2:AC$10000, ">=4.0")>0, "〇", "×"))) -> 〇 | K7: =IF(OR($A7="", K$5=""), "", IF(COUNTIFS(【データ】蓄積用!A$2:A$10000, K$5, 【データ】蓄積用!C$2:C$10000, $A7, 【データ】蓄積用!D$2:D$10000, ">=3000", 【データ】蓄積用!E$2:E$10000, ">=1500")>0, "〇", IF(COUNTIFS(【データ】蓄積用!A$2:A$10000, K$5, 【データ】蓄積用!C$2:C$10000, $A7, 【データ】蓄積用!Q$2:Q$10000, 1, 【データ】蓄積用!AC$2:AC$10000, ">=4.0")>0, "〇", "×"))) -> × | L7: =IF(OR($A7="", L$5=""), "", IF(COUNTIFS(【データ】蓄積用!A$2:A$10000, L$5, 【データ】蓄積用!C$2:C$10000, $A7, 【データ】蓄積用!D$2:D$10000, ">=3000", 【データ】蓄積用!E$2:E$10000, ">=1500")>0, "〇", IF(COUNTIFS(【データ】蓄積用!A$2:A$10000, L$5, 【データ】蓄積用!C$2:C$10000, $A7, 【データ】蓄積用!Q$2:Q$10000, 1, 【データ】蓄積用!AC$2:AC$10000, ">=4.0")>0, "〇", "×"))) -> × | M7: =IF(OR($A7="", M$5=""), "", IF(COUNTIFS(【データ】蓄積用!A$2:A$10000, M$5, 【データ】蓄積用!C$2:C$10000, $A7, 【データ】蓄積用!D$2:D$10000, ">=3000", 【データ】蓄積用!E$2:E$10000, ">=1500")>0, "〇", IF(COUNTIFS(【データ】蓄積用!A$2:A$10000, M$5, 【データ】蓄積用!C$2:C$10000, $A7, 【データ】蓄積用!Q$2:Q$10000, 1, 【データ】蓄積用!AC$2:AC$10000, ">=4.0")>0, "〇", "×"))) -> × | N7: =IF(OR($A7="", N$5=""), "", IF(COUNTIFS(【データ】蓄積用!A$2:A$10000, N$5, 【データ】蓄積用!C$2:C$10000, $A7, 【データ】蓄積用!D$2:D$10000, ">=3000", 【データ】蓄積用!E$2:E$10000, ">=1500")>0, "〇", IF(COUNTIFS(【データ】蓄積用!A$2:A$10000, N$5, 【データ】蓄積用!C$2:C$10000, $A7, 【データ】蓄積用!Q$2:Q$10000, 1, 【データ】蓄積用!AC$2:AC$10000, ">=4.0")>0, "〇", "×"))) -> × | O7: =IF(OR($A7="", O$5=""), "", IF(COUNTIFS(【データ】蓄積用!A$2:A$10000, O$5, 【データ】蓄積用!C$2:C$10000, $A7, 【データ】蓄積用!D$2:D$10000, ">=3000", 【データ】蓄積用!E$2:E$10000, ">=1500")>0, "〇", IF(COUNTIFS(【データ】蓄積用!A$2:A$10000, O$5, 【データ】蓄積用!C$2:C$10000, $A7, 【データ】蓄積用!Q$2:Q$10000, 1, 【データ】蓄積用!AC$2:AC$10000, ">=4.0")>0, "〇", "×"))) -> × | P7: =IF(OR($A7="", P$5=""), "", IF(COUNTIFS(【データ】蓄積用!A$2:A$10000, P$5, 【データ】蓄積用!C$2:C$10000, $A7, 【データ】蓄積用!D$2:D$10000, ">=3000", 【データ】蓄積用!E$2:E$10000, ">=1500")>0, "〇", IF(COUNTIFS(【データ】蓄積用!A$2:A$10000, P$5, 【データ】蓄積用!C$2:C$10000, $A7, 【データ】蓄積用!Q$2:Q$10000, 1, 【データ】蓄積用!AC$2:AC$10000, ">=4.0")>0, "〇", "×"))) -> 〇 | Q7: =IF(OR($A7="", Q$5=""), "", IF(COUNTIFS(【データ】蓄積用!A$2:A$10000, Q$5, 【データ】蓄積用!C$2:C$10000, $A7, 【データ】蓄積用!D$2:D$10000, ">=3000", 【データ】蓄積用!E$2:E$10000, ">=1500")>0, "〇", IF(COUNTIFS(【データ】蓄積用!A$2:A$10000, Q$5, 【データ】蓄積用!C$2:C$10000, $A7, 【データ】蓄積用!Q$2:Q$10000, 1, 【データ】蓄積用!AC$2:AC$10000, ">=4.0")>0, "〇", "×"))) -> × | R7: =IF(OR($A7="", R$5=""), "", IF(COUNTIFS(【データ】蓄積用!A$2:A$10000, R$5, 【データ】蓄積用!C$2:C$10000, $A7, 【データ】蓄積用!D$2:D$10000, ">=3000", 【データ】蓄積用!E$2:E$10000, ">=1500")>0, "〇", IF(COUNTIFS(【データ】蓄積用!A$2:A$10000, R$5, 【データ】蓄積用!C$2:C$10000, $A7, 【データ】蓄積用!Q$2:Q$10000, 1, 【データ】蓄積用!AC$2:AC$10000, ">=4.0")>0, "〇", "×"))) -> × | S7: =IF(OR($A7="", S$5=""), "", IF(COUNTIFS(【データ】蓄積用!A$2:A$10000, S$5, 【データ】蓄積用!C$2:C$10000, $A7, 【データ】蓄積用!D$2:D$10000, ">=3000", 【データ】蓄積用!E$2:E$10000, ">=1500")>0, "〇", IF(COUNTIFS(【データ】蓄積用!A$2:A$10000, S$5, 【データ】蓄積用!C$2:C$10000, $A7, 【データ】蓄積用!Q$2:Q$10000, 1, 【データ】蓄積用!AC$2:AC$10000, ">=4.0")>0, "〇", "×"))) -> × | T7: =IF(OR($A7="", T$5=""), "", IF(COUNTIFS(【データ】蓄積用!A$2:A$10000, T$5, 【データ】蓄積用!C$2:C$10000, $A7, 【データ】蓄積用!D$2:D$10000, ">=3000", 【データ】蓄積用!E$2:E$10000, ">=1500")>0, "〇", IF(COUNTIFS(【データ】蓄積用!A$2:A$10000, T$5, 【データ】蓄積用!C$2:C$10000, $A7, 【データ】蓄積用!Q$2:Q$10000, 1, 【データ】蓄積用!AC$2:AC$10000, ">=4.0")>0, "〇", "×"))) -> × | U7: =IF(OR($A7="", U$5=""), "", IF(COUNTIFS(【データ】蓄積用!A$2:A$10000, U$5, 【データ】蓄積用!C$2:C$10000, $A7, 【データ】蓄積用!D$2:D$10000, ">=3000", 【データ】蓄積用!E$2:E$10000, ">=1500")>0, "〇", IF(COUNTIFS(【データ】蓄積用!A$2:A$10000, U$5, 【データ】蓄積用!C$2:C$10000, $A7, 【データ】蓄積用!Q$2:Q$10000, 1, 【データ】蓄積用!AC$2:AC$10000, ">=4.0")>0, "〇", "×"))) -> × | V7: =IF(OR($A7="", V$5=""), "", IF(COUNTIFS(【データ】蓄積用!A$2:A$10000, V$5, 【データ】蓄積用!C$2:C$10000, $A7, 【データ】蓄積用!D$2:D$10000, ">=3000", 【データ】蓄積用!E$2:E$10000, ">=1500")>0, "〇", IF(COUNTIFS(【データ】蓄積用!A$2:A$10000, V$5, 【データ】蓄積用!C$2:C$10000, $A7, 【データ】蓄積用!Q$2:Q$10000, 1, 【データ】蓄積用!AC$2:AC$10000, ">=4.0")>0, "〇", "×"))) -> 〇 | W7: =IF(OR($A7="", W$5=""), "", IF(COUNTIFS(【データ】蓄積用!A$2:A$10000, W$5, 【データ】蓄積用!C$2:C$10000, $A7, 【データ】蓄積用!D$2:D$10000, ">=3000", 【データ】蓄積用!E$2:E$10000, ">=1500")>0, "〇", IF(COUNTIFS(【データ】蓄積用!A$2:A$10000, W$5, 【データ】蓄積用!C$2:C$10000, $A7, 【データ】蓄積用!Q$2:Q$10000, 1, 【データ】蓄積用!AC$2:AC$10000, ">=4.0")>0, "〇", "×"))) -> × | X7: =IF(OR($A7="", X$5=""), "", IF(COUNTIFS(【データ】蓄積用!A$2:A$10000, X$5, 【データ】蓄積用!C$2:C$10000, $A7, 【データ】蓄積用!D$2:D$10000, ">=3000", 【データ】蓄積用!E$2:E$10000, ">=1500")>0, "〇", IF(COUNTIFS(【データ】蓄積用!A$2:A$10000, X$5, 【データ】蓄積用!C$2:C$10000, $A7, 【データ】蓄積用!Q$2:Q$10000, 1, 【データ】蓄積用!AC$2:AC$10000, ">=4.0")>0, "〇", "×"))) -> × | Y7: =IF(OR($A7="", Y$5=""), "", IF(COUNTIFS(【データ】蓄積用!A$2:A$10000, Y$5, 【データ】蓄積用!C$2:C$10000, $A7, 【データ】蓄積用!D$2:D$10000, ">=3000", 【データ】蓄積用!E$2:E$10000, ">=1500")>0, "〇", IF(COUNTIFS(【データ】蓄積用!A$2:A$10000, Y$5, 【データ】蓄積用!C$2:C$10000, $A7, 【データ】蓄積用!Q$2:Q$10000, 1, 【データ】蓄積用!AC$2:AC$10000, ">=4.0")>0, "〇", "×"))) -> × | Z7: =IF(OR($A7="", Z$5=""), "", IF(COUNTIFS(【データ】蓄積用!A$2:A$10000, Z$5, 【データ】蓄積用!C$2:C$10000, $A7, 【データ】蓄積用!D$2:D$10000, ">=3000", 【データ】蓄積用!E$2:E$10000, ">=1500")>0, "〇", IF(COUNTIFS(【データ】蓄積用!A$2:A$10000, Z$5, 【データ】蓄積用!C$2:C$10000, $A7, 【データ】蓄積用!Q$2:Q$10000, 1, 【データ】蓄積用!AC$2:AC$10000, ">=4.0")>0, "〇", "×"))) -> × | AA7: =IF(OR($A7="", AA$5=""), "", IF(COUNTIFS(【データ】蓄積用!A$2:A$10000, AA$5, 【データ】蓄積用!C$2:C$10000, $A7, 【データ】蓄積用!D$2:D$10000, ">=3000", 【データ】蓄積用!E$2:E$10000, ">=1500")>0, "〇", IF(COUNTIFS(【データ】蓄積用!A$2:A$10000, AA$5, 【データ】蓄積用!C$2:C$10000, $A7, 【データ】蓄積用!Q$2:Q$10000, 1, 【データ】蓄積用!AC$2:AC$10000, ">=4.0")>0, "〇", "×"))) -> × | AB7: =IF(OR($A7="", AB$5=""), "", IF(COUNTIFS(【データ】蓄積用!A$2:A$10000, AB$5, 【データ】蓄積用!C$2:C$10000, $A7, 【データ】蓄積用!D$2:D$10000, ">=3000", 【データ】蓄積用!E$2:E$10000, ">=1500")>0, "〇", IF(COUNTIFS(【データ】蓄積用!A$2:A$10000, AB$5, 【データ】蓄積用!C$2:C$10000, $A7, 【データ】蓄積用!Q$2:Q$10000, 1, 【データ】蓄積用!AC$2:AC$10000, ">=4.0")>0, "〇", "×"))) -> 〇 | AC7: =IF(OR($A7="", AC$5=""), "", IF(COUNTIFS(【データ】蓄積用!A$2:A$10000, AC$5, 【データ】蓄積用!C$2:C$10000, $A7, 【データ】蓄積用!D$2:D$10000, ">=3000", 【データ】蓄積用!E$2:E$10000, ">=1500")>0, "〇", IF(COUNTIFS(【データ】蓄積用!A$2:A$10000, AC$5, 【データ】蓄積用!C$2:C$10000, $A7, 【データ】蓄積用!Q$2:Q$10000, 1, 【データ】蓄積用!AC$2:AC$10000, ">=4.0")>0, "〇", "×"))) -> × | AD7: =IF(OR($A7="", AD$5=""), "", IF(COUNTIFS(【データ】蓄積用!A$2:A$10000, AD$5, 【データ】蓄積用!C$2:C$10000, $A7, 【データ】蓄積用!D$2:D$10000, ">=3000", 【データ】蓄積用!E$2:E$10000, ">=1500")>0, "〇", IF(COUNTIFS(【データ】蓄積用!A$2:A$10000, AD$5, 【データ】蓄積用!C$2:C$10000, $A7, 【データ】蓄積用!Q$2:Q$10000, 1, 【データ】蓄積用!AC$2:AC$10000, ">=4.0")>0, "〇", "×"))) -> × | AE7: =IF(OR($A7="", AE$5=""), "", IF(COUNTIFS(【データ】蓄積用!A$2:A$10000, AE$5, 【データ】蓄積用!C$2:C$10000, $A7, 【データ】蓄積用!D$2:D$10000, ">=3000", 【データ】蓄積用!E$2:E$10000, ">=1500")>0, "〇", IF(COUNTIFS(【データ】蓄積用!A$2:A$10000, AE$5, 【データ】蓄積用!C$2:C$10000, $A7, 【データ】蓄積用!Q$2:Q$10000, 1, 【データ】蓄積用!AC$2:AC$10000, ">=4.0")>0, "〇", "×"))) -> × | AF7: =IF(OR($A7="", AF$5=""), "", IF(COUNTIFS(【データ】蓄積用!A$2:A$10000, AF$5, 【データ】蓄積用!C$2:C$10000, $A7, 【データ】蓄積用!D$2:D$10000, ">=3000", 【データ】蓄積用!E$2:E$10000, ">=1500")>0, "〇", IF(COUNTIFS(【データ】蓄積用!A$2:A$10000, AF$5, 【データ】蓄積用!C$2:C$10000, $A7, 【データ】蓄積用!Q$2:Q$10000, 1, 【データ】蓄積用!AC$2:AC$10000, ">=4.0")>0, "〇", "×"))) -> × | AG7: =IF(OR($A7="", AG$5=""), "", IF(COUNTIFS(【データ】蓄積用!A$2:A$10000, AG$5, 【データ】蓄積用!C$2:C$10000, $A7, 【データ】蓄積用!D$2:D$10000, ">=3000", 【データ】蓄積用!E$2:E$10000, ">=1500")>0, "〇", IF(COUNTIFS(【データ】蓄積用!A$2:A$10000, AG$5, 【データ】蓄積用!C$2:C$10000, $A7, 【データ】蓄積用!Q$2:Q$10000, 1, 【データ】蓄積用!AC$2:AC$10000, ">=4.0")>0, "〇", "×"))) -> × | AH7: =IF(OR($A7="", AH$5=""), "", IF(COUNTIFS(【データ】蓄積用!A$2:A$10000, AH$5, 【データ】蓄積用!C$2:C$10000, $A7, 【データ】蓄積用!D$2:D$10000, ">=3000", 【データ】蓄積用!E$2:E$10000, ">=1500")>0, "〇", IF(COUNTIFS(【データ】蓄積用!A$2:A$10000, AH$5, 【データ】蓄積用!C$2:C$10000, $A7, 【データ】蓄積用!Q$2:Q$10000, 1, 【データ】蓄積用!AC$2:AC$10000, ">=4.0")>0, "〇", "×"))) -> × | AI7: =IF(OR($A7="", AI$5=""), "", IF(COUNTIFS(【データ】蓄積用!A$2:A$10000, AI$5, 【データ】蓄積用!C$2:C$10000, $A7, 【データ】蓄積用!D$2:D$10000, ">=3000", 【データ】蓄積用!E$2:E$10000, ">=1500")>0, "〇", IF(COUNTIFS(【データ】蓄積用!A$2:A$10000, AI$5, 【データ】蓄積用!C$2:C$10000, $A7, 【データ】蓄積用!Q$2:Q$10000, 1, 【データ】蓄積用!AC$2:AC$10000, ">=4.0")>0, "〇", "×"))) -> × | AJ7: =IF(OR($A7="", AJ$5=""), "", IF(COUNTIFS(【データ】蓄積用!A$2:A$10000, AJ$5, 【データ】蓄積用!C$2:C$10000, $A7, 【データ】蓄積用!D$2:D$10000, ">=3000", 【データ】蓄積用!E$2:E$10000, ">=1500")>0, "〇", IF(COUNTIFS(【データ】蓄積用!A$2:A$10000, AJ$5, 【データ】蓄積用!C$2:C$10000, $A7, 【データ】蓄積用!Q$2:Q$10000, 1, 【データ】蓄積用!AC$2:AC$10000, ">=4.0")>0, "〇", "×"))) -> × | AK7: =IF(OR($A7="", AK$5=""), "", IF(COUNTIFS(【データ】蓄積用!A$2:A$10000, AK$5, 【データ】蓄積用!C$2:C$10000, $A7, 【データ】蓄積用!D$2:D$10000, ">=3000", 【データ】蓄積用!E$2:E$10000, ">=1500")>0, "〇", IF(COUNTIFS(【データ】蓄積用!A$2:A$10000, AK$5, 【データ】蓄積用!C$2:C$10000, $A7, 【データ】蓄積用!Q$2:Q$10000, 1, 【データ】蓄積用!AC$2:AC$10000, ">=4.0")>0, "〇", "×"))) -> × | AL7: =IF(OR($A7="", AL$5=""), "", IF(COUNTIFS(【データ】蓄積用!A$2:A$10000, AL$5, 【データ】蓄積用!C$2:C$10000, $A7, 【データ】蓄積用!D$2:D$10000, ">=3000", 【データ】蓄積用!E$2:E$10000, ">=1500")>0, "〇", IF(COUNTIFS(【データ】蓄積用!A$2:A$10000, AL$5, 【データ】蓄積用!C$2:C$10000, $A7, 【データ】蓄積用!Q$2:Q$10000, 1, 【データ】蓄積用!AC$2:AC$10000, ">=4.0")>0, "〇", "×"))) -> × | AM7: =IF(OR($A7="", AM$5=""), "", IF(COUNTIFS(【データ】蓄積用!A$2:A$10000, AM$5, 【データ】蓄積用!C$2:C$10000, $A7, 【データ】蓄積用!D$2:D$10000, ">=3000", 【データ】蓄積用!E$2:E$10000, ">=1500")>0, "〇", IF(COUNTIFS(【データ】蓄積用!A$2:A$10000, AM$5, 【データ】蓄積用!C$2:C$10000, $A7, 【データ】蓄積用!Q$2:Q$10000, 1, 【データ】蓄積用!AC$2:AC$10000, ">=4.0")>0, "〇", "×"))) -> × | AN7: =IF(OR($A7="", AN$5=""), "", IF(COUNTIFS(【データ】蓄積用!A$2:A$10000, AN$5, 【データ】蓄積用!C$2:C$10000, $A7, 【データ】蓄積用!D$2:D$10000, ">=3000", 【データ】蓄積用!E$2:E$10000, ">=1500")>0, "〇", IF(COUNTIFS(【データ】蓄積用!A$2:A$10000, AN$5, 【データ】蓄積用!C$2:C$10000, $A7, 【データ】蓄積用!Q$2:Q$10000, 1, 【データ】蓄積用!AC$2:AC$10000, ">=4.0")>0, "〇", "×"))) -> × | AO7: =IF(OR($A7="", AO$5=""), "", IF(COUNTIFS(【データ】蓄積用!A$2:A$10000, AO$5, 【データ】蓄積用!C$2:C$10000, $A7, 【データ】蓄積用!D$2:D$10000, ">=3000", 【データ】蓄積用!E$2:E$10000, ">=1500")>0, "〇", IF(COUNTIFS(【データ】蓄積用!A$2:A$10000, AO$5, 【データ】蓄積用!C$2:C$10000, $A7, 【データ】蓄積用!Q$2:Q$10000, 1, 【データ】蓄積用!AC$2:AC$10000, ">=4.0")>0, "〇", "×"))) -> × | AP7: =IF(OR($A7="", AP$5=""), "", IF(COUNTIFS(【データ】蓄積用!A$2:A$10000, AP$5, 【データ】蓄積用!C$2:C$10000, $A7, 【データ】蓄積用!D$2:D$10000, ">=3000", 【データ】蓄積用!E$2:E$10000, ">=1500")>0, "〇", IF(COUNTIFS(【データ】蓄積用!A$2:A$10000, AP$5, 【データ】蓄積用!C$2:C$10000, $A7, 【データ】蓄積用!Q$2:Q$10000, 1, 【データ】蓄積用!AC$2:AC$10000, ">=4.0")>0, "〇", "×"))) -> × | AQ7: =IF(OR($A7="", AQ$5=""), "", IF(COUNTIFS(【データ】蓄積用!A$2:A$10000, AQ$5, 【データ】蓄積用!C$2:C$10000, $A7, 【データ】蓄積用!D$2:D$10000, ">=3000", 【データ】蓄積用!E$2:E$10000, ">=1500")>0, "〇", IF(COUNTIFS(【データ】蓄積用!A$2:A$10000, AQ$5, 【データ】蓄積用!C$2:C$10000, $A7, 【データ】蓄積用!Q$2:Q$10000, 1, 【データ】蓄積用!AC$2:AC$10000, ">=4.0")>0, "〇", "×"))) -> × | AR7: =IF(OR($A7="", AR$5=""), "", IF(COUNTIFS(【データ】蓄積用!A$2:A$10000, AR$5, 【データ】蓄積用!C$2:C$10000, $A7, 【データ】蓄積用!D$2:D$10000, ">=3000", 【データ】蓄積用!E$2:E$10000, ">=1500")>0, "〇", IF(COUNTIFS(【データ】蓄積用!A$2:A$10000, AR$5, 【データ】蓄積用!C$2:C$10000, $A7, 【データ】蓄積用!Q$2:Q$10000, 1, 【データ】蓄積用!AC$2:AC$10000, ">=4.0")>0, "〇", "×"))) -> × | AS7: =IF(OR($A7="", AS$5=""), "", IF(COUNTIFS(【データ】蓄積用!A$2:A$10000, AS$5, 【データ】蓄積用!C$2:C$10000, $A7, 【データ】蓄積用!D$2:D$10000, ">=3000", 【データ】蓄積用!E$2:E$10000, ">=1500")>0, "〇", IF(COUNTIFS(【データ】蓄積用!A$2:A$10000, AS$5, 【データ】蓄積用!C$2:C$10000, $A7, 【データ】蓄積用!Q$2:Q$10000, 1, 【データ】蓄積用!AC$2:AC$10000, ">=4.0")>0, "〇", "×"))) -> × | AT7: =IF(OR($A7="", AT$5=""), "", IF(COUNTIFS(【データ】蓄積用!A$2:A$10000, AT$5, 【データ】蓄積用!C$2:C$10000, $A7, 【データ】蓄積用!D$2:D$10000, ">=3000", 【データ】蓄積用!E$2:E$10000, ">=1500")>0, "〇", IF(COUNTIFS(【データ】蓄積用!A$2:A$10000, AT$5, 【データ】蓄積用!C$2:C$10000, $A7, 【データ】蓄積用!Q$2:Q$10000, 1, 【データ】蓄積用!AC$2:AC$10000, ">=4.0")>0, "〇", "×"))) -> × | AU7: =IF(OR($A7="", AU$5=""), "", IF(COUNTIFS(【データ】蓄積用!A$2:A$10000, AU$5, 【データ】蓄積用!C$2:C$10000, $A7, 【データ】蓄積用!D$2:D$10000, ">=3000", 【データ】蓄積用!E$2:E$10000, ">=1500")>0, "〇", IF(COUNTIFS(【データ】蓄積用!A$2:A$10000, AU$5, 【データ】蓄積用!C$2:C$10000, $A7, 【データ】蓄積用!Q$2:Q$10000, 1, 【データ】蓄積用!AC$2:AC$10000, ">=4.0")>0, "〇", "×"))) -> × | AV7: =IF(OR($A7="", AV$5=""), "", IF(COUNTIFS(【データ】蓄積用!A$2:A$10000, AV$5, 【データ】蓄積用!C$2:C$10000, $A7, 【データ】蓄積用!D$2:D$10000, ">=3000", 【データ】蓄積用!E$2:E$10000, ">=1500")>0, "〇", IF(COUNTIFS(【データ】蓄積用!A$2:A$10000, AV$5, 【データ】蓄積用!C$2:C$10000, $A7, 【データ】蓄積用!Q$2:Q$10000, 1, 【データ】蓄積用!AC$2:AC$10000, ">=4.0")>0, "〇", "×"))) -> × | AW7: =IF(OR($A7="", AW$5=""), "", IF(COUNTIFS(【データ】蓄積用!A$2:A$10000, AW$5, 【データ】蓄積用!C$2:C$10000, $A7, 【データ】蓄積用!D$2:D$10000, ">=3000", 【データ】蓄積用!E$2:E$10000, ">=1500")>0, "〇", IF(COUNTIFS(【データ】蓄積用!A$2:A$10000, AW$5, 【データ】蓄積用!C$2:C$10000, $A7, 【データ】蓄積用!Q$2:Q$10000, 1, 【データ】蓄積用!AC$2:AC$10000, ">=4.0")>0, "〇", "×"))) -> × | AX7: =IF(OR($A7="", AX$5=""), "", IF(COUNTIFS(【データ】蓄積用!A$2:A$10000, AX$5, 【データ】蓄積用!C$2:C$10000, $A7, 【データ】蓄積用!D$2:D$10000, ">=3000", 【データ】蓄積用!E$2:E$10000, ">=1500")>0, "〇", IF(COUNTIFS(【データ】蓄積用!A$2:A$10000, AX$5, 【データ】蓄積用!C$2:C$10000, $A7, 【データ】蓄積用!Q$2:Q$10000, 1, 【データ】蓄積用!AC$2:AC$10000, ">=4.0")>0, "〇", "×"))) -> × | AY7: =IF(OR($A7="", AY$5=""), "", IF(COUNTIFS(【データ】蓄積用!A$2:A$10000, AY$5, 【データ】蓄積用!C$2:C$10000, $A7, 【データ】蓄積用!D$2:D$10000, ">=3000", 【データ】蓄積用!E$2:E$10000, ">=1500")>0, "〇", IF(COUNTIFS(【データ】蓄積用!A$2:A$10000, AY$5, 【データ】蓄積用!C$2:C$10000, $A7, 【データ】蓄積用!Q$2:Q$10000, 1, 【データ】蓄積用!AC$2:AC$10000, ">=4.0")>0, "〇", "×")))
A8: 502 | B8: =IF(OR($A8="", B$5=""), "", IF(COUNTIFS(【データ】蓄積用!A$2:A$10000, B$5, 【データ】蓄積用!C$2:C$10000, $A8, 【データ】蓄積用!D$2:D$10000, ">=3000", 【データ】蓄積用!E$2:E$10000, ">=1500")>0, "〇", IF(COUNTIFS(【データ】蓄積用!A$2:A$10000, B$5, 【データ】蓄積用!C$2:C$10000, $A8, 【データ】蓄積用!Q$2:Q$10000, 1, 【データ】蓄積用!AC$2:AC$10000, ">=4.0")>0, "〇", "×"))) -> × | C8: =IF(OR($A8="", C$5=""), "", IF(COUNTIFS(【データ】蓄積用!A$2:A$10000, C$5, 【データ】蓄積用!C$2:C$10000, $A8, 【データ】蓄積用!D$2:D$10000, ">=3000", 【データ】蓄積用!E$2:E$10000, ">=1500")>0, "〇", IF(COUNTIFS(【データ】蓄積用!A$2:A$10000, C$5, 【データ】蓄積用!C$2:C$10000, $A8, 【データ】蓄積用!Q$2:Q$10000, 1, 【データ】蓄積用!AC$2:AC$10000, ">=4.0")>0, "〇", "×"))) -> × | D8: =IF(OR($A8="", D$5=""), "", IF(COUNTIFS(【データ】蓄積用!A$2:A$10000, D$5, 【データ】蓄積用!C$2:C$10000, $A8, 【データ】蓄積用!D$2:D$10000, ">=3000", 【データ】蓄積用!E$2:E$10000, ">=1500")>0, "〇", IF(COUNTIFS(【データ】蓄積用!A$2:A$10000, D$5, 【データ】蓄積用!C$2:C$10000, $A8, 【データ】蓄積用!Q$2:Q$10000, 1, 【データ】蓄積用!AC$2:AC$10000, ">=4.0")>0, "〇", "×"))) -> × | E8: =IF(OR($A8="", E$5=""), "", IF(COUNTIFS(【データ】蓄積用!A$2:A$10000, E$5, 【データ】蓄積用!C$2:C$10000, $A8, 【データ】蓄積用!D$2:D$10000, ">=3000", 【データ】蓄積用!E$2:E$10000, ">=1500")>0, "〇", IF(COUNTIFS(【データ】蓄積用!A$2:A$10000, E$5, 【データ】蓄積用!C$2:C$10000, $A8, 【データ】蓄積用!Q$2:Q$10000, 1, 【データ】蓄積用!AC$2:AC$10000, ">=4.0")>0, "〇", "×"))) -> × | F8: =IF(OR($A8="", F$5=""), "", IF(COUNTIFS(【データ】蓄積用!A$2:A$10000, F$5, 【データ】蓄積用!C$2:C$10000, $A8, 【データ】蓄積用!D$2:D$10000, ">=3000", 【データ】蓄積用!E$2:E$10000, ">=1500")>0, "〇", IF(COUNTIFS(【データ】蓄積用!A$2:A$10000, F$5, 【データ】蓄積用!C$2:C$10000, $A8, 【データ】蓄積用!Q$2:Q$10000, 1, 【データ】蓄積用!AC$2:AC$10000, ">=4.0")>0, "〇", "×"))) -> × | G8: =IF(OR($A8="", G$5=""), "", IF(COUNTIFS(【データ】蓄積用!A$2:A$10000, G$5, 【データ】蓄積用!C$2:C$10000, $A8, 【データ】蓄積用!D$2:D$10000, ">=3000", 【データ】蓄積用!E$2:E$10000, ">=1500")>0, "〇", IF(COUNTIFS(【データ】蓄積用!A$2:A$10000, G$5, 【データ】蓄積用!C$2:C$10000, $A8, 【データ】蓄積用!Q$2:Q$10000, 1, 【データ】蓄積用!AC$2:AC$10000, ">=4.0")>0, "〇", "×"))) -> × | H8: =IF(OR($A8="", H$5=""), "", IF(COUNTIFS(【データ】蓄積用!A$2:A$10000, H$5, 【データ】蓄積用!C$2:C$10000, $A8, 【データ】蓄積用!D$2:D$10000, ">=3000", 【データ】蓄積用!E$2:E$10000, ">=1500")>0, "〇", IF(COUNTIFS(【データ】蓄積用!A$2:A$10000, H$5, 【データ】蓄積用!C$2:C$10000, $A8, 【データ】蓄積用!Q$2:Q$10000, 1, 【データ】蓄積用!AC$2:AC$10000, ">=4.0")>0, "〇", "×"))) -> × | I8: =IF(OR($A8="", I$5=""), "", IF(COUNTIFS(【データ】蓄積用!A$2:A$10000, I$5, 【データ】蓄積用!C$2:C$10000, $A8, 【データ】蓄積用!D$2:D$10000, ">=3000", 【データ】蓄積用!E$2:E$10000, ">=1500")>0, "〇", IF(COUNTIFS(【データ】蓄積用!A$2:A$10000, I$5, 【データ】蓄積用!C$2:C$10000, $A8, 【データ】蓄積用!Q$2:Q$10000, 1, 【データ】蓄積用!AC$2:AC$10000, ">=4.0")>0, "〇", "×"))) -> × | J8: =IF(OR($A8="", J$5=""), "", IF(COUNTIFS(【データ】蓄積用!A$2:A$10000, J$5, 【データ】蓄積用!C$2:C$10000, $A8, 【データ】蓄積用!D$2:D$10000, ">=3000", 【データ】蓄積用!E$2:E$10000, ">=1500")>0, "〇", IF(COUNTIFS(【データ】蓄積用!A$2:A$10000, J$5, 【データ】蓄積用!C$2:C$10000, $A8, 【データ】蓄積用!Q$2:Q$10000, 1, 【データ】蓄積用!AC$2:AC$10000, ">=4.0")>0, "〇", "×"))) -> × | K8: =IF(OR($A8="", K$5=""), "", IF(COUNTIFS(【データ】蓄積用!A$2:A$10000, K$5, 【データ】蓄積用!C$2:C$10000, $A8, 【データ】蓄積用!D$2:D$10000, ">=3000", 【データ】蓄積用!E$2:E$10000, ">=1500")>0, "〇", IF(COUNTIFS(【データ】蓄積用!A$2:A$10000, K$5, 【データ】蓄積用!C$2:C$10000, $A8, 【データ】蓄積用!Q$2:Q$10000, 1, 【データ】蓄積用!AC$2:AC$10000, ">=4.0")>0, "〇", "×"))) -> × | L8: =IF(OR($A8="", L$5=""), "", IF(COUNTIFS(【データ】蓄積用!A$2:A$10000, L$5, 【データ】蓄積用!C$2:C$10000, $A8, 【データ】蓄積用!D$2:D$10000, ">=3000", 【データ】蓄積用!E$2:E$10000, ">=1500")>0, "〇", IF(COUNTIFS(【データ】蓄積用!A$2:A$10000, L$5, 【データ】蓄積用!C$2:C$10000, $A8, 【データ】蓄積用!Q$2:Q$10000, 1, 【データ】蓄積用!AC$2:AC$10000, ">=4.0")>0, "〇", "×"))) -> × | M8: =IF(OR($A8="", M$5=""), "", IF(COUNTIFS(【データ】蓄積用!A$2:A$10000, M$5, 【データ】蓄積用!C$2:C$10000, $A8, 【データ】蓄積用!D$2:D$10000, ">=3000", 【データ】蓄積用!E$2:E$10000, ">=1500")>0, "〇", IF(COUNTIFS(【データ】蓄積用!A$2:A$10000, M$5, 【データ】蓄積用!C$2:C$10000, $A8, 【データ】蓄積用!Q$2:Q$10000, 1, 【データ】蓄積用!AC$2:AC$10000, ">=4.0")>0, "〇", "×"))) -> × | N8: =IF(OR($A8="", N$5=""), "", IF(COUNTIFS(【データ】蓄積用!A$2:A$10000, N$5, 【データ】蓄積用!C$2:C$10000, $A8, 【データ】蓄積用!D$2:D$10000, ">=3000", 【データ】蓄積用!E$2:E$10000, ">=1500")>0, "〇", IF(COUNTIFS(【データ】蓄積用!A$2:A$10000, N$5, 【データ】蓄積用!C$2:C$10000, $A8, 【データ】蓄積用!Q$2:Q$10000, 1, 【データ】蓄積用!AC$2:AC$10000, ">=4.0")>0, "〇", "×"))) -> × | O8: =IF(OR($A8="", O$5=""), "", IF(COUNTIFS(【データ】蓄積用!A$2:A$10000, O$5, 【データ】蓄積用!C$2:C$10000, $A8, 【データ】蓄積用!D$2:D$10000, ">=3000", 【データ】蓄積用!E$2:E$10000, ">=1500")>0, "〇", IF(COUNTIFS(【データ】蓄積用!A$2:A$10000, O$5, 【データ】蓄積用!C$2:C$10000, $A8, 【データ】蓄積用!Q$2:Q$10000, 1, 【データ】蓄積用!AC$2:AC$10000, ">=4.0")>0, "〇", "×"))) -> × | P8: =IF(OR($A8="", P$5=""), "", IF(COUNTIFS(【データ】蓄積用!A$2:A$10000, P$5, 【データ】蓄積用!C$2:C$10000, $A8, 【データ】蓄積用!D$2:D$10000, ">=3000", 【データ】蓄積用!E$2:E$10000, ">=1500")>0, "〇", IF(COUNTIFS(【データ】蓄積用!A$2:A$10000, P$5, 【データ】蓄積用!C$2:C$10000, $A8, 【データ】蓄積用!Q$2:Q$10000, 1, 【データ】蓄積用!AC$2:AC$10000, ">=4.0")>0, "〇", "×"))) -> × | Q8: =IF(OR($A8="", Q$5=""), "", IF(COUNTIFS(【データ】蓄積用!A$2:A$10000, Q$5, 【データ】蓄積用!C$2:C$10000, $A8, 【データ】蓄積用!D$2:D$10000, ">=3000", 【データ】蓄積用!E$2:E$10000, ">=1500")>0, "〇", IF(COUNTIFS(【データ】蓄積用!A$2:A$10000, Q$5, 【データ】蓄積用!C$2:C$10000, $A8, 【データ】蓄積用!Q$2:Q$10000, 1, 【データ】蓄積用!AC$2:AC$10000, ">=4.0")>0, "〇", "×"))) -> × | R8: =IF(OR($A8="", R$5=""), "", IF(COUNTIFS(【データ】蓄積用!A$2:A$10000, R$5, 【データ】蓄積用!C$2:C$10000, $A8, 【データ】蓄積用!D$2:D$10000, ">=3000", 【データ】蓄積用!E$2:E$10000, ">=1500")>0, "〇", IF(COUNTIFS(【データ】蓄積用!A$2:A$10000, R$5, 【データ】蓄積用!C$2:C$10000, $A8, 【データ】蓄積用!Q$2:Q$10000, 1, 【データ】蓄積用!AC$2:AC$10000, ">=4.0")>0, "〇", "×"))) -> × | S8: =IF(OR($A8="", S$5=""), "", IF(COUNTIFS(【データ】蓄積用!A$2:A$10000, S$5, 【データ】蓄積用!C$2:C$10000, $A8, 【データ】蓄積用!D$2:D$10000, ">=3000", 【データ】蓄積用!E$2:E$10000, ">=1500")>0, "〇", IF(COUNTIFS(【データ】蓄積用!A$2:A$10000, S$5, 【データ】蓄積用!C$2:C$10000, $A8, 【データ】蓄積用!Q$2:Q$10000, 1, 【データ】蓄積用!AC$2:AC$10000, ">=4.0")>0, "〇", "×"))) -> × | T8: =IF(OR($A8="", T$5=""), "", IF(COUNTIFS(【データ】蓄積用!A$2:A$10000, T$5, 【データ】蓄積用!C$2:C$10000, $A8, 【データ】蓄積用!D$2:D$10000, ">=3000", 【データ】蓄積用!E$2:E$10000, ">=1500")>0, "〇", IF(COUNTIFS(【データ】蓄積用!A$2:A$10000, T$5, 【データ】蓄積用!C$2:C$10000, $A8, 【データ】蓄積用!Q$2:Q$10000, 1, 【データ】蓄積用!AC$2:AC$10000, ">=4.0")>0, "〇", "×"))) -> × | U8: =IF(OR($A8="", U$5=""), "", IF(COUNTIFS(【データ】蓄積用!A$2:A$10000, U$5, 【データ】蓄積用!C$2:C$10000, $A8, 【データ】蓄積用!D$2:D$10000, ">=3000", 【データ】蓄積用!E$2:E$10000, ">=1500")>0, "〇", IF(COUNTIFS(【データ】蓄積用!A$2:A$10000, U$5, 【データ】蓄積用!C$2:C$10000, $A8, 【データ】蓄積用!Q$2:Q$10000, 1, 【データ】蓄積用!AC$2:AC$10000, ">=4.0")>0, "〇", "×"))) -> × | V8: =IF(OR($A8="", V$5=""), "", IF(COUNTIFS(【データ】蓄積用!A$2:A$10000, V$5, 【データ】蓄積用!C$2:C$10000, $A8, 【データ】蓄積用!D$2:D$10000, ">=3000", 【データ】蓄積用!E$2:E$10000, ">=1500")>0, "〇", IF(COUNTIFS(【データ】蓄積用!A$2:A$10000, V$5, 【データ】蓄積用!C$2:C$10000, $A8, 【データ】蓄積用!Q$2:Q$10000, 1, 【データ】蓄積用!AC$2:AC$10000, ">=4.0")>0, "〇", "×"))) -> × | W8: =IF(OR($A8="", W$5=""), "", IF(COUNTIFS(【データ】蓄積用!A$2:A$10000, W$5, 【データ】蓄積用!C$2:C$10000, $A8, 【データ】蓄積用!D$2:D$10000, ">=3000", 【データ】蓄積用!E$2:E$10000, ">=1500")>0, "〇", IF(COUNTIFS(【データ】蓄積用!A$2:A$10000, W$5, 【データ】蓄積用!C$2:C$10000, $A8, 【データ】蓄積用!Q$2:Q$10000, 1, 【データ】蓄積用!AC$2:AC$10000, ">=4.0")>0, "〇", "×"))) -> × | X8: =IF(OR($A8="", X$5=""), "", IF(COUNTIFS(【データ】蓄積用!A$2:A$10000, X$5, 【データ】蓄積用!C$2:C$10000, $A8, 【データ】蓄積用!D$2:D$10000, ">=3000", 【データ】蓄積用!E$2:E$10000, ">=1500")>0, "〇", IF(COUNTIFS(【データ】蓄積用!A$2:A$10000, X$5, 【データ】蓄積用!C$2:C$10000, $A8, 【データ】蓄積用!Q$2:Q$10000, 1, 【データ】蓄積用!AC$2:AC$10000, ">=4.0")>0, "〇", "×"))) -> × | Y8: =IF(OR($A8="", Y$5=""), "", IF(COUNTIFS(【データ】蓄積用!A$2:A$10000, Y$5, 【データ】蓄積用!C$2:C$10000, $A8, 【データ】蓄積用!D$2:D$10000, ">=3000", 【データ】蓄積用!E$2:E$10000, ">=1500")>0, "〇", IF(COUNTIFS(【データ】蓄積用!A$2:A$10000, Y$5, 【データ】蓄積用!C$2:C$10000, $A8, 【データ】蓄積用!Q$2:Q$10000, 1, 【データ】蓄積用!AC$2:AC$10000, ">=4.0")>0, "〇", "×"))) -> × | Z8: =IF(OR($A8="", Z$5=""), "", IF(COUNTIFS(【データ】蓄積用!A$2:A$10000, Z$5, 【データ】蓄積用!C$2:C$10000, $A8, 【データ】蓄積用!D$2:D$10000, ">=3000", 【データ】蓄積用!E$2:E$10000, ">=1500")>0, "〇", IF(COUNTIFS(【データ】蓄積用!A$2:A$10000, Z$5, 【データ】蓄積用!C$2:C$10000, $A8, 【データ】蓄積用!Q$2:Q$10000, 1, 【データ】蓄積用!AC$2:AC$10000, ">=4.0")>0, "〇", "×"))) -> × | AA8: =IF(OR($A8="", AA$5=""), "", IF(COUNTIFS(【データ】蓄積用!A$2:A$10000, AA$5, 【データ】蓄積用!C$2:C$10000, $A8, 【データ】蓄積用!D$2:D$10000, ">=3000", 【データ】蓄積用!E$2:E$10000, ">=1500")>0, "〇", IF(COUNTIFS(【データ】蓄積用!A$2:A$10000, AA$5, 【データ】蓄積用!C$2:C$10000, $A8, 【データ】蓄積用!Q$2:Q$10000, 1, 【データ】蓄積用!AC$2:AC$10000, ">=4.0")>0, "〇", "×"))) -> × | AB8: =IF(OR($A8="", AB$5=""), "", IF(COUNTIFS(【データ】蓄積用!A$2:A$10000, AB$5, 【データ】蓄積用!C$2:C$10000, $A8, 【データ】蓄積用!D$2:D$10000, ">=3000", 【データ】蓄積用!E$2:E$10000, ">=1500")>0, "〇", IF(COUNTIFS(【データ】蓄積用!A$2:A$10000, AB$5, 【データ】蓄積用!C$2:C$10000, $A8, 【データ】蓄積用!Q$2:Q$10000, 1, 【データ】蓄積用!AC$2:AC$10000, ">=4.0")>0, "〇", "×"))) -> × | AC8: =IF(OR($A8="", AC$5=""), "", IF(COUNTIFS(【データ】蓄積用!A$2:A$10000, AC$5, 【データ】蓄積用!C$2:C$10000, $A8, 【データ】蓄積用!D$2:D$10000, ">=3000", 【データ】蓄積用!E$2:E$10000, ">=1500")>0, "〇", IF(COUNTIFS(【データ】蓄積用!A$2:A$10000, AC$5, 【データ】蓄積用!C$2:C$10000, $A8, 【データ】蓄積用!Q$2:Q$10000, 1, 【データ】蓄積用!AC$2:AC$10000, ">=4.0")>0, "〇", "×"))) -> × | AD8: =IF(OR($A8="", AD$5=""), "", IF(COUNTIFS(【データ】蓄積用!A$2:A$10000, AD$5, 【データ】蓄積用!C$2:C$10000, $A8, 【データ】蓄積用!D$2:D$10000, ">=3000", 【データ】蓄積用!E$2:E$10000, ">=1500")>0, "〇", IF(COUNTIFS(【データ】蓄積用!A$2:A$10000, AD$5, 【データ】蓄積用!C$2:C$10000, $A8, 【データ】蓄積用!Q$2:Q$10000, 1, 【データ】蓄積用!AC$2:AC$10000, ">=4.0")>0, "〇", "×"))) -> × | AE8: =IF(OR($A8="", AE$5=""), "", IF(COUNTIFS(【データ】蓄積用!A$2:A$10000, AE$5, 【データ】蓄積用!C$2:C$10000, $A8, 【データ】蓄積用!D$2:D$10000, ">=3000", 【データ】蓄積用!E$2:E$10000, ">=1500")>0, "〇", IF(COUNTIFS(【データ】蓄積用!A$2:A$10000, AE$5, 【データ】蓄積用!C$2:C$10000, $A8, 【データ】蓄積用!Q$2:Q$10000, 1, 【データ】蓄積用!AC$2:AC$10000, ">=4.0")>0, "〇", "×"))) -> × | AF8: =IF(OR($A8="", AF$5=""), "", IF(COUNTIFS(【データ】蓄積用!A$2:A$10000, AF$5, 【データ】蓄積用!C$2:C$10000, $A8, 【データ】蓄積用!D$2:D$10000, ">=3000", 【データ】蓄積用!E$2:E$10000, ">=1500")>0, "〇", IF(COUNTIFS(【データ】蓄積用!A$2:A$10000, AF$5, 【データ】蓄積用!C$2:C$10000, $A8, 【データ】蓄積用!Q$2:Q$10000, 1, 【データ】蓄積用!AC$2:AC$10000, ">=4.0")>0, "〇", "×"))) -> × | AG8: =IF(OR($A8="", AG$5=""), "", IF(COUNTIFS(【データ】蓄積用!A$2:A$10000, AG$5, 【データ】蓄積用!C$2:C$10000, $A8, 【データ】蓄積用!D$2:D$10000, ">=3000", 【データ】蓄積用!E$2:E$10000, ">=1500")>0, "〇", IF(COUNTIFS(【データ】蓄積用!A$2:A$10000, AG$5, 【データ】蓄積用!C$2:C$10000, $A8, 【データ】蓄積用!Q$2:Q$10000, 1, 【データ】蓄積用!AC$2:AC$10000, ">=4.0")>0, "〇", "×"))) -> × | AH8: =IF(OR($A8="", AH$5=""), "", IF(COUNTIFS(【データ】蓄積用!A$2:A$10000, AH$5, 【データ】蓄積用!C$2:C$10000, $A8, 【データ】蓄積用!D$2:D$10000, ">=3000", 【データ】蓄積用!E$2:E$10000, ">=1500")>0, "〇", IF(COUNTIFS(【データ】蓄積用!A$2:A$10000, AH$5, 【データ】蓄積用!C$2:C$10000, $A8, 【データ】蓄積用!Q$2:Q$10000, 1, 【データ】蓄積用!AC$2:AC$10000, ">=4.0")>0, "〇", "×"))) -> × | AI8: =IF(OR($A8="", AI$5=""), "", IF(COUNTIFS(【データ】蓄積用!A$2:A$10000, AI$5, 【データ】蓄積用!C$2:C$10000, $A8, 【データ】蓄積用!D$2:D$10000, ">=3000", 【データ】蓄積用!E$2:E$10000, ">=1500")>0, "〇", IF(COUNTIFS(【データ】蓄積用!A$2:A$10000, AI$5, 【データ】蓄積用!C$2:C$10000, $A8, 【データ】蓄積用!Q$2:Q$10000, 1, 【データ】蓄積用!AC$2:AC$10000, ">=4.0")>0, "〇", "×"))) -> × | AJ8: =IF(OR($A8="", AJ$5=""), "", IF(COUNTIFS(【データ】蓄積用!A$2:A$10000, AJ$5, 【データ】蓄積用!C$2:C$10000, $A8, 【データ】蓄積用!D$2:D$10000, ">=3000", 【データ】蓄積用!E$2:E$10000, ">=1500")>0, "〇", IF(COUNTIFS(【データ】蓄積用!A$2:A$10000, AJ$5, 【データ】蓄積用!C$2:C$10000, $A8, 【データ】蓄積用!Q$2:Q$10000, 1, 【データ】蓄積用!AC$2:AC$10000, ">=4.0")>0, "〇", "×"))) -> × | AK8: =IF(OR($A8="", AK$5=""), "", IF(COUNTIFS(【データ】蓄積用!A$2:A$10000, AK$5, 【データ】蓄積用!C$2:C$10000, $A8, 【データ】蓄積用!D$2:D$10000, ">=3000", 【データ】蓄積用!E$2:E$10000, ">=1500")>0, "〇", IF(COUNTIFS(【データ】蓄積用!A$2:A$10000, AK$5, 【データ】蓄積用!C$2:C$10000, $A8, 【データ】蓄積用!Q$2:Q$10000, 1, 【データ】蓄積用!AC$2:AC$10000, ">=4.0")>0, "〇", "×"))) -> 〇 | AL8: =IF(OR($A8="", AL$5=""), "", IF(COUNTIFS(【データ】蓄積用!A$2:A$10000, AL$5, 【データ】蓄積用!C$2:C$10000, $A8, 【データ】蓄積用!D$2:D$10000, ">=3000", 【データ】蓄積用!E$2:E$10000, ">=1500")>0, "〇", IF(COUNTIFS(【データ】蓄積用!A$2:A$10000, AL$5, 【データ】蓄積用!C$2:C$10000, $A8, 【データ】蓄積用!Q$2:Q$10000, 1, 【データ】蓄積用!AC$2:AC$10000, ">=4.0")>0, "〇", "×"))) -> × | AM8: =IF(OR($A8="", AM$5=""), "", IF(COUNTIFS(【データ】蓄積用!A$2:A$10000, AM$5, 【データ】蓄積用!C$2:C$10000, $A8, 【データ】蓄積用!D$2:D$10000, ">=3000", 【データ】蓄積用!E$2:E$10000, ">=1500")>0, "〇", IF(COUNTIFS(【データ】蓄積用!A$2:A$10000, AM$5, 【データ】蓄積用!C$2:C$10000, $A8, 【データ】蓄積用!Q$2:Q$10000, 1, 【データ】蓄積用!AC$2:AC$10000, ">=4.0")>0, "〇", "×"))) -> 〇 | AN8: =IF(OR($A8="", AN$5=""), "", IF(COUNTIFS(【データ】蓄積用!A$2:A$10000, AN$5, 【データ】蓄積用!C$2:C$10000, $A8, 【データ】蓄積用!D$2:D$10000, ">=3000", 【データ】蓄積用!E$2:E$10000, ">=1500")>0, "〇", IF(COUNTIFS(【データ】蓄積用!A$2:A$10000, AN$5, 【データ】蓄積用!C$2:C$10000, $A8, 【データ】蓄積用!Q$2:Q$10000, 1, 【データ】蓄積用!AC$2:AC$10000, ">=4.0")>0, "〇", "×"))) -> × | AO8: =IF(OR($A8="", AO$5=""), "", IF(COUNTIFS(【データ】蓄積用!A$2:A$10000, AO$5, 【データ】蓄積用!C$2:C$10000, $A8, 【データ】蓄積用!D$2:D$10000, ">=3000", 【データ】蓄積用!E$2:E$10000, ">=1500")>0, "〇", IF(COUNTIFS(【データ】蓄積用!A$2:A$10000, AO$5, 【データ】蓄積用!C$2:C$10000, $A8, 【データ】蓄積用!Q$2:Q$10000, 1, 【データ】蓄積用!AC$2:AC$10000, ">=4.0")>0, "〇", "×"))) -> × | AP8: =IF(OR($A8="", AP$5=""), "", IF(COUNTIFS(【データ】蓄積用!A$2:A$10000, AP$5, 【データ】蓄積用!C$2:C$10000, $A8, 【データ】蓄積用!D$2:D$10000, ">=3000", 【データ】蓄積用!E$2:E$10000, ">=1500")>0, "〇", IF(COUNTIFS(【データ】蓄積用!A$2:A$10000, AP$5, 【データ】蓄積用!C$2:C$10000, $A8, 【データ】蓄積用!Q$2:Q$10000, 1, 【データ】蓄積用!AC$2:AC$10000, ">=4.0")>0, "〇", "×"))) -> × | AQ8: =IF(OR($A8="", AQ$5=""), "", IF(COUNTIFS(【データ】蓄積用!A$2:A$10000, AQ$5, 【データ】蓄積用!C$2:C$10000, $A8, 【データ】蓄積用!D$2:D$10000, ">=3000", 【データ】蓄積用!E$2:E$10000, ">=1500")>0, "〇", IF(COUNTIFS(【データ】蓄積用!A$2:A$10000, AQ$5, 【データ】蓄積用!C$2:C$10000, $A8, 【データ】蓄積用!Q$2:Q$10000, 1, 【データ】蓄積用!AC$2:AC$10000, ">=4.0")>0, "〇", "×"))) -> × | AR8: =IF(OR($A8="", AR$5=""), "", IF(COUNTIFS(【データ】蓄積用!A$2:A$10000, AR$5, 【データ】蓄積用!C$2:C$10000, $A8, 【データ】蓄積用!D$2:D$10000, ">=3000", 【データ】蓄積用!E$2:E$10000, ">=1500")>0, "〇", IF(COUNTIFS(【データ】蓄積用!A$2:A$10000, AR$5, 【データ】蓄積用!C$2:C$10000, $A8, 【データ】蓄積用!Q$2:Q$10000, 1, 【データ】蓄積用!AC$2:AC$10000, ">=4.0")>0, "〇", "×"))) -> × | AS8: =IF(OR($A8="", AS$5=""), "", IF(COUNTIFS(【データ】蓄積用!A$2:A$10000, AS$5, 【データ】蓄積用!C$2:C$10000, $A8, 【データ】蓄積用!D$2:D$10000, ">=3000", 【データ】蓄積用!E$2:E$10000, ">=1500")>0, "〇", IF(COUNTIFS(【データ】蓄積用!A$2:A$10000, AS$5, 【データ】蓄積用!C$2:C$10000, $A8, 【データ】蓄積用!Q$2:Q$10000, 1, 【データ】蓄積用!AC$2:AC$10000, ">=4.0")>0, "〇", "×"))) -> × | AT8: =IF(OR($A8="", AT$5=""), "", IF(COUNTIFS(【データ】蓄積用!A$2:A$10000, AT$5, 【データ】蓄積用!C$2:C$10000, $A8, 【データ】蓄積用!D$2:D$10000, ">=3000", 【データ】蓄積用!E$2:E$10000, ">=1500")>0, "〇", IF(COUNTIFS(【データ】蓄積用!A$2:A$10000, AT$5, 【データ】蓄積用!C$2:C$10000, $A8, 【データ】蓄積用!Q$2:Q$10000, 1, 【データ】蓄積用!AC$2:AC$10000, ">=4.0")>0, "〇", "×"))) -> × | AU8: =IF(OR($A8="", AU$5=""), "", IF(COUNTIFS(【データ】蓄積用!A$2:A$10000, AU$5, 【データ】蓄積用!C$2:C$10000, $A8, 【データ】蓄積用!D$2:D$10000, ">=3000", 【データ】蓄積用!E$2:E$10000, ">=1500")>0, "〇", IF(COUNTIFS(【データ】蓄積用!A$2:A$10000, AU$5, 【データ】蓄積用!C$2:C$10000, $A8, 【データ】蓄積用!Q$2:Q$10000, 1, 【データ】蓄積用!AC$2:AC$10000, ">=4.0")>0, "〇", "×"))) -> × | AV8: =IF(OR($A8="", AV$5=""), "", IF(COUNTIFS(【データ】蓄積用!A$2:A$10000, AV$5, 【データ】蓄積用!C$2:C$10000, $A8, 【データ】蓄積用!D$2:D$10000, ">=3000", 【データ】蓄積用!E$2:E$10000, ">=1500")>0, "〇", IF(COUNTIFS(【データ】蓄積用!A$2:A$10000, AV$5, 【データ】蓄積用!C$2:C$10000, $A8, 【データ】蓄積用!Q$2:Q$10000, 1, 【データ】蓄積用!AC$2:AC$10000, ">=4.0")>0, "〇", "×"))) -> × | AW8: =IF(OR($A8="", AW$5=""), "", IF(COUNTIFS(【データ】蓄積用!A$2:A$10000, AW$5, 【データ】蓄積用!C$2:C$10000, $A8, 【データ】蓄積用!D$2:D$10000, ">=3000", 【データ】蓄積用!E$2:E$10000, ">=1500")>0, "〇", IF(COUNTIFS(【データ】蓄積用!A$2:A$10000, AW$5, 【データ】蓄積用!C$2:C$10000, $A8, 【データ】蓄積用!Q$2:Q$10000, 1, 【データ】蓄積用!AC$2:AC$10000, ">=4.0")>0, "〇", "×"))) -> × | AX8: =IF(OR($A8="", AX$5=""), "", IF(COUNTIFS(【データ】蓄積用!A$2:A$10000, AX$5, 【データ】蓄積用!C$2:C$10000, $A8, 【データ】蓄積用!D$2:D$10000, ">=3000", 【データ】蓄積用!E$2:E$10000, ">=1500")>0, "〇", IF(COUNTIFS(【データ】蓄積用!A$2:A$10000, AX$5, 【データ】蓄積用!C$2:C$10000, $A8, 【データ】蓄積用!Q$2:Q$10000, 1, 【データ】蓄積用!AC$2:AC$10000, ">=4.0")>0, "〇", "×"))) -> 〇 | AY8: =IF(OR($A8="", AY$5=""), "", IF(COUNTIFS(【データ】蓄積用!A$2:A$10000, AY$5, 【データ】蓄積用!C$2:C$10000, $A8, 【データ】蓄積用!D$2:D$10000, ">=3000", 【データ】蓄積用!E$2:E$10000, ">=1500")>0, "〇", IF(COUNTIFS(【データ】蓄積用!A$2:A$10000, AY$5, 【データ】蓄積用!C$2:C$10000, $A8, 【データ】蓄積用!Q$2:Q$10000, 1, 【データ】蓄積用!AC$2:AC$10000, ">=4.0")>0, "〇", "×")))
A9: 503 | B9: =IF(OR($A9="", B$5=""), "", IF(COUNTIFS(【データ】蓄積用!A$2:A$10000, B$5, 【データ】蓄積用!C$2:C$10000, $A9, 【データ】蓄積用!D$2:D$10000, ">=3000", 【データ】蓄積用!E$2:E$10000, ">=1500")>0, "〇", IF(COUNTIFS(【データ】蓄積用!A$2:A$10000, B$5, 【データ】蓄積用!C$2:C$10000, $A9, 【データ】蓄積用!Q$2:Q$10000, 1, 【データ】蓄積用!AC$2:AC$10000, ">=4.0")>0, "〇", "×"))) -> × | C9: =IF(OR($A9="", C$5=""), "", IF(COUNTIFS(【データ】蓄積用!A$2:A$10000, C$5, 【データ】蓄積用!C$2:C$10000, $A9, 【データ】蓄積用!D$2:D$10000, ">=3000", 【データ】蓄積用!E$2:E$10000, ">=1500")>0, "〇", IF(COUNTIFS(【データ】蓄積用!A$2:A$10000, C$5, 【データ】蓄積用!C$2:C$10000, $A9, 【データ】蓄積用!Q$2:Q$10000, 1, 【データ】蓄積用!AC$2:AC$10000, ">=4.0")>0, "〇", "×"))) -> × | D9: =IF(OR($A9="", D$5=""), "", IF(COUNTIFS(【データ】蓄積用!A$2:A$10000, D$5, 【データ】蓄積用!C$2:C$10000, $A9, 【データ】蓄積用!D$2:D$10000, ">=3000", 【データ】蓄積用!E$2:E$10000, ">=1500")>0, "〇", IF(COUNTIFS(【データ】蓄積用!A$2:A$10000, D$5, 【データ】蓄積用!C$2:C$10000, $A9, 【データ】蓄積用!Q$2:Q$10000, 1, 【データ】蓄積用!AC$2:AC$10000, ">=4.0")>0, "〇", "×"))) -> × | E9: =IF(OR($A9="", E$5=""), "", IF(COUNTIFS(【データ】蓄積用!A$2:A$10000, E$5, 【データ】蓄積用!C$2:C$10000, $A9, 【データ】蓄積用!D$2:D$10000, ">=3000", 【データ】蓄積用!E$2:E$10000, ">=1500")>0, "〇", IF(COUNTIFS(【データ】蓄積用!A$2:A$10000, E$5, 【データ】蓄積用!C$2:C$10000, $A9, 【データ】蓄積用!Q$2:Q$10000, 1, 【データ】蓄積用!AC$2:AC$10000, ">=4.0")>0, "〇", "×"))) -> × | F9: =IF(OR($A9="", F$5=""), "", IF(COUNTIFS(【データ】蓄積用!A$2:A$10000, F$5, 【データ】蓄積用!C$2:C$10000, $A9, 【データ】蓄積用!D$2:D$10000, ">=3000", 【データ】蓄積用!E$2:E$10000, ">=1500")>0, "〇", IF(COUNTIFS(【データ】蓄積用!A$2:A$10000, F$5, 【データ】蓄積用!C$2:C$10000, $A9, 【データ】蓄積用!Q$2:Q$10000, 1, 【データ】蓄積用!AC$2:AC$10000, ">=4.0")>0, "〇", "×"))) -> × | G9: =IF(OR($A9="", G$5=""), "", IF(COUNTIFS(【データ】蓄積用!A$2:A$10000, G$5, 【データ】蓄積用!C$2:C$10000, $A9, 【データ】蓄積用!D$2:D$10000, ">=3000", 【データ】蓄積用!E$2:E$10000, ">=1500")>0, "〇", IF(COUNTIFS(【データ】蓄積用!A$2:A$10000, G$5, 【データ】蓄積用!C$2:C$10000, $A9, 【データ】蓄積用!Q$2:Q$10000, 1, 【データ】蓄積用!AC$2:AC$10000, ">=4.0")>0, "〇", "×"))) -> × | H9: =IF(OR($A9="", H$5=""), "", IF(COUNTIFS(【データ】蓄積用!A$2:A$10000, H$5, 【データ】蓄積用!C$2:C$10000, $A9, 【データ】蓄積用!D$2:D$10000, ">=3000", 【データ】蓄積用!E$2:E$10000, ">=1500")>0, "〇", IF(COUNTIFS(【データ】蓄積用!A$2:A$10000, H$5, 【データ】蓄積用!C$2:C$10000, $A9, 【データ】蓄積用!Q$2:Q$10000, 1, 【データ】蓄積用!AC$2:AC$10000, ">=4.0")>0, "〇", "×"))) -> 〇 | I9: =IF(OR($A9="", I$5=""), "", IF(COUNTIFS(【データ】蓄積用!A$2:A$10000, I$5, 【データ】蓄積用!C$2:C$10000, $A9, 【データ】蓄積用!D$2:D$10000, ">=3000", 【データ】蓄積用!E$2:E$10000, ">=1500")>0, "〇", IF(COUNTIFS(【データ】蓄積用!A$2:A$10000, I$5, 【データ】蓄積用!C$2:C$10000, $A9, 【データ】蓄積用!Q$2:Q$10000, 1, 【データ】蓄積用!AC$2:AC$10000, ">=4.0")>0, "〇", "×"))) -> × | J9: =IF(OR($A9="", J$5=""), "", IF(COUNTIFS(【データ】蓄積用!A$2:A$10000, J$5, 【データ】蓄積用!C$2:C$10000, $A9, 【データ】蓄積用!D$2:D$10000, ">=3000", 【データ】蓄積用!E$2:E$10000, ">=1500")>0, "〇", IF(COUNTIFS(【データ】蓄積用!A$2:A$10000, J$5, 【データ】蓄積用!C$2:C$10000, $A9, 【データ】蓄積用!Q$2:Q$10000, 1, 【データ】蓄積用!AC$2:AC$10000, ">=4.0")>0, "〇", "×"))) -> × | K9: =IF(OR($A9="", K$5=""), "", IF(COUNTIFS(【データ】蓄積用!A$2:A$10000, K$5, 【データ】蓄積用!C$2:C$10000, $A9, 【データ】蓄積用!D$2:D$10000, ">=3000", 【データ】蓄積用!E$2:E$10000, ">=1500")>0, "〇", IF(COUNTIFS(【データ】蓄積用!A$2:A$10000, K$5, 【データ】蓄積用!C$2:C$10000, $A9, 【データ】蓄積用!Q$2:Q$10000, 1, 【データ】蓄積用!AC$2:AC$10000, ">=4.0")>0, "〇", "×"))) -> × | L9: =IF(OR($A9="", L$5=""), "", IF(COUNTIFS(【データ】蓄積用!A$2:A$10000, L$5, 【データ】蓄積用!C$2:C$10000, $A9, 【データ】蓄積用!D$2:D$10000, ">=3000", 【データ】蓄積用!E$2:E$10000, ">=1500")>0, "〇", IF(COUNTIFS(【データ】蓄積用!A$2:A$10000, L$5, 【データ】蓄積用!C$2:C$10000, $A9, 【データ】蓄積用!Q$2:Q$10000, 1, 【データ】蓄積用!AC$2:AC$10000, ">=4.0")>0, "〇", "×"))) -> × | M9: =IF(OR($A9="", M$5=""), "", IF(COUNTIFS(【データ】蓄積用!A$2:A$10000, M$5, 【データ】蓄積用!C$2:C$10000, $A9, 【データ】蓄積用!D$2:D$10000, ">=3000", 【データ】蓄積用!E$2:E$10000, ">=1500")>0, "〇", IF(COUNTIFS(【データ】蓄積用!A$2:A$10000, M$5, 【データ】蓄積用!C$2:C$10000, $A9, 【データ】蓄積用!Q$2:Q$10000, 1, 【データ】蓄積用!AC$2:AC$10000, ">=4.0")>0, "〇", "×"))) -> × | N9: =IF(OR($A9="", N$5=""), "", IF(COUNTIFS(【データ】蓄積用!A$2:A$10000, N$5, 【データ】蓄積用!C$2:C$10000, $A9, 【データ】蓄積用!D$2:D$10000, ">=3000", 【データ】蓄積用!E$2:E$10000, ">=1500")>0, "〇", IF(COUNTIFS(【データ】蓄積用!A$2:A$10000, N$5, 【データ】蓄積用!C$2:C$10000, $A9, 【データ】蓄積用!Q$2:Q$10000, 1, 【データ】蓄積用!AC$2:AC$10000, ">=4.0")>0, "〇", "×"))) -> × | O9: =IF(OR($A9="", O$5=""), "", IF(COUNTIFS(【データ】蓄積用!A$2:A$10000, O$5, 【データ】蓄積用!C$2:C$10000, $A9, 【データ】蓄積用!D$2:D$10000, ">=3000", 【データ】蓄積用!E$2:E$10000, ">=1500")>0, "〇", IF(COUNTIFS(【データ】蓄積用!A$2:A$10000, O$5, 【データ】蓄積用!C$2:C$10000, $A9, 【データ】蓄積用!Q$2:Q$10000, 1, 【データ】蓄積用!AC$2:AC$10000, ">=4.0")>0, "〇", "×"))) -> × | P9: =IF(OR($A9="", P$5=""), "", IF(COUNTIFS(【データ】蓄積用!A$2:A$10000, P$5, 【データ】蓄積用!C$2:C$10000, $A9, 【データ】蓄積用!D$2:D$10000, ">=3000", 【データ】蓄積用!E$2:E$10000, ">=1500")>0, "〇", IF(COUNTIFS(【データ】蓄積用!A$2:A$10000, P$5, 【データ】蓄積用!C$2:C$10000, $A9, 【データ】蓄積用!Q$2:Q$10000, 1, 【データ】蓄積用!AC$2:AC$10000, ">=4.0")>0, "〇", "×"))) -> × | Q9: =IF(OR($A9="", Q$5=""), "", IF(COUNTIFS(【データ】蓄積用!A$2:A$10000, Q$5, 【データ】蓄積用!C$2:C$10000, $A9, 【データ】蓄積用!D$2:D$10000, ">=3000", 【データ】蓄積用!E$2:E$10000, ">=1500")>0, "〇", IF(COUNTIFS(【データ】蓄積用!A$2:A$10000, Q$5, 【データ】蓄積用!C$2:C$10000, $A9, 【データ】蓄積用!Q$2:Q$10000, 1, 【データ】蓄積用!AC$2:AC$10000, ">=4.0")>0, "〇", "×"))) -> × | R9: =IF(OR($A9="", R$5=""), "", IF(COUNTIFS(【データ】蓄積用!A$2:A$10000, R$5, 【データ】蓄積用!C$2:C$10000, $A9, 【データ】蓄積用!D$2:D$10000, ">=3000", 【データ】蓄積用!E$2:E$10000, ">=1500")>0, "〇", IF(COUNTIFS(【データ】蓄積用!A$2:A$10000, R$5, 【データ】蓄積用!C$2:C$10000, $A9, 【データ】蓄積用!Q$2:Q$10000, 1, 【データ】蓄積用!AC$2:AC$10000, ">=4.0")>0, "〇", "×"))) -> × | S9: =IF(OR($A9="", S$5=""), "", IF(COUNTIFS(【データ】蓄積用!A$2:A$10000, S$5, 【データ】蓄積用!C$2:C$10000, $A9, 【データ】蓄積用!D$2:D$10000, ">=3000", 【データ】蓄積用!E$2:E$10000, ">=1500")>0, "〇", IF(COUNTIFS(【データ】蓄積用!A$2:A$10000, S$5, 【データ】蓄積用!C$2:C$10000, $A9, 【データ】蓄積用!Q$2:Q$10000, 1, 【データ】蓄積用!AC$2:AC$10000, ">=4.0")>0, "〇", "×"))) -> 〇 | T9: =IF(OR($A9="", T$5=""), "", IF(COUNTIFS(【データ】蓄積用!A$2:A$10000, T$5, 【データ】蓄積用!C$2:C$10000, $A9, 【データ】蓄積用!D$2:D$10000, ">=3000", 【データ】蓄積用!E$2:E$10000, ">=1500")>0, "〇", IF(COUNTIFS(【データ】蓄積用!A$2:A$10000, T$5, 【データ】蓄積用!C$2:C$10000, $A9, 【データ】蓄積用!Q$2:Q$10000, 1, 【データ】蓄積用!AC$2:AC$10000, ">=4.0")>0, "〇", "×"))) -> × | U9: =IF(OR($A9="", U$5=""), "", IF(COUNTIFS(【データ】蓄積用!A$2:A$10000, U$5, 【データ】蓄積用!C$2:C$10000, $A9, 【データ】蓄積用!D$2:D$10000, ">=3000", 【データ】蓄積用!E$2:E$10000, ">=1500")>0, "〇", IF(COUNTIFS(【データ】蓄積用!A$2:A$10000, U$5, 【データ】蓄積用!C$2:C$10000, $A9, 【データ】蓄積用!Q$2:Q$10000, 1, 【データ】蓄積用!AC$2:AC$10000, ">=4.0")>0, "〇", "×"))) -> 〇 | V9: =IF(OR($A9="", V$5=""), "", IF(COUNTIFS(【データ】蓄積用!A$2:A$10000, V$5, 【データ】蓄積用!C$2:C$10000, $A9, 【データ】蓄積用!D$2:D$10000, ">=3000", 【データ】蓄積用!E$2:E$10000, ">=1500")>0, "〇", IF(COUNTIFS(【データ】蓄積用!A$2:A$10000, V$5, 【データ】蓄積用!C$2:C$10000, $A9, 【データ】蓄積用!Q$2:Q$10000, 1, 【データ】蓄積用!AC$2:AC$10000, ">=4.0")>0, "〇", "×"))) -> × | W9: =IF(OR($A9="", W$5=""), "", IF(COUNTIFS(【データ】蓄積用!A$2:A$10000, W$5, 【データ】蓄積用!C$2:C$10000, $A9, 【データ】蓄積用!D$2:D$10000, ">=3000", 【データ】蓄積用!E$2:E$10000, ">=1500")>0, "〇", IF(COUNTIFS(【データ】蓄積用!A$2:A$10000, W$5, 【データ】蓄積用!C$2:C$10000, $A9, 【データ】蓄積用!Q$2:Q$10000, 1, 【データ】蓄積用!AC$2:AC$10000, ">=4.0")>0, "〇", "×"))) -> × | X9: =IF(OR($A9="", X$5=""), "", IF(COUNTIFS(【データ】蓄積用!A$2:A$10000, X$5, 【データ】蓄積用!C$2:C$10000, $A9, 【データ】蓄積用!D$2:D$10000, ">=3000", 【データ】蓄積用!E$2:E$10000, ">=1500")>0, "〇", IF(COUNTIFS(【データ】蓄積用!A$2:A$10000, X$5, 【データ】蓄積用!C$2:C$10000, $A9, 【データ】蓄積用!Q$2:Q$10000, 1, 【データ】蓄積用!AC$2:AC$10000, ">=4.0")>0, "〇", "×"))) -> × | Y9: =IF(OR($A9="", Y$5=""), "", IF(COUNTIFS(【データ】蓄積用!A$2:A$10000, Y$5, 【データ】蓄積用!C$2:C$10000, $A9, 【データ】蓄積用!D$2:D$10000, ">=3000", 【データ】蓄積用!E$2:E$10000, ">=1500")>0, "〇", IF(COUNTIFS(【データ】蓄積用!A$2:A$10000, Y$5, 【データ】蓄積用!C$2:C$10000, $A9, 【データ】蓄積用!Q$2:Q$10000, 1, 【データ】蓄積用!AC$2:AC$10000, ">=4.0")>0, "〇", "×"))) -> × | Z9: =IF(OR($A9="", Z$5=""), "", IF(COUNTIFS(【データ】蓄積用!A$2:A$10000, Z$5, 【データ】蓄積用!C$2:C$10000, $A9, 【データ】蓄積用!D$2:D$10000, ">=3000", 【データ】蓄積用!E$2:E$10000, ">=1500")>0, "〇", IF(COUNTIFS(【データ】蓄積用!A$2:A$10000, Z$5, 【データ】蓄積用!C$2:C$10000, $A9, 【データ】蓄積用!Q$2:Q$10000, 1, 【データ】蓄積用!AC$2:AC$10000, ">=4.0")>0, "〇", "×"))) -> 〇 | AA9: =IF(OR($A9="", AA$5=""), "", IF(COUNTIFS(【データ】蓄積用!A$2:A$10000, AA$5, 【データ】蓄積用!C$2:C$10000, $A9, 【データ】蓄積用!D$2:D$10000, ">=3000", 【データ】蓄積用!E$2:E$10000, ">=1500")>0, "〇", IF(COUNTIFS(【データ】蓄積用!A$2:A$10000, AA$5, 【データ】蓄積用!C$2:C$10000, $A9, 【データ】蓄積用!Q$2:Q$10000, 1, 【データ】蓄積用!AC$2:AC$10000, ">=4.0")>0, "〇", "×"))) -> × | AB9: =IF(OR($A9="", AB$5=""), "", IF(COUNTIFS(【データ】蓄積用!A$2:A$10000, AB$5, 【データ】蓄積用!C$2:C$10000, $A9, 【データ】蓄積用!D$2:D$10000, ">=3000", 【データ】蓄積用!E$2:E$10000, ">=1500")>0, "〇", IF(COUNTIFS(【データ】蓄積用!A$2:A$10000, AB$5, 【データ】蓄積用!C$2:C$10000, $A9, 【データ】蓄積用!Q$2:Q$10000, 1, 【データ】蓄積用!AC$2:AC$10000, ">=4.0")>0, "〇", "×"))) -> × | AC9: =IF(OR($A9="", AC$5=""), "", IF(COUNTIFS(【データ】蓄積用!A$2:A$10000, AC$5, 【データ】蓄積用!C$2:C$10000, $A9, 【データ】蓄積用!D$2:D$10000, ">=3000", 【データ】蓄積用!E$2:E$10000, ">=1500")>0, "〇", IF(COUNTIFS(【データ】蓄積用!A$2:A$10000, AC$5, 【データ】蓄積用!C$2:C$10000, $A9, 【データ】蓄積用!Q$2:Q$10000, 1, 【データ】蓄積用!AC$2:AC$10000, ">=4.0")>0, "〇", "×"))) -> × | AD9: =IF(OR($A9="", AD$5=""), "", IF(COUNTIFS(【データ】蓄積用!A$2:A$10000, AD$5, 【データ】蓄積用!C$2:C$10000, $A9, 【データ】蓄積用!D$2:D$10000, ">=3000", 【データ】蓄積用!E$2:E$10000, ">=1500")>0, "〇", IF(COUNTIFS(【データ】蓄積用!A$2:A$10000, AD$5, 【データ】蓄積用!C$2:C$10000, $A9, 【データ】蓄積用!Q$2:Q$10000, 1, 【データ】蓄積用!AC$2:AC$10000, ">=4.0")>0, "〇", "×"))) -> 〇 | AE9: =IF(OR($A9="", AE$5=""), "", IF(COUNTIFS(【データ】蓄積用!A$2:A$10000, AE$5, 【データ】蓄積用!C$2:C$10000, $A9, 【データ】蓄積用!D$2:D$10000, ">=3000", 【データ】蓄積用!E$2:E$10000, ">=1500")>0, "〇", IF(COUNTIFS(【データ】蓄積用!A$2:A$10000, AE$5, 【データ】蓄積用!C$2:C$10000, $A9, 【データ】蓄積用!Q$2:Q$10000, 1, 【データ】蓄積用!AC$2:AC$10000, ">=4.0")>0, "〇", "×"))) -> × | AF9: =IF(OR($A9="", AF$5=""), "", IF(COUNTIFS(【データ】蓄積用!A$2:A$10000, AF$5, 【データ】蓄積用!C$2:C$10000, $A9, 【データ】蓄積用!D$2:D$10000, ">=3000", 【データ】蓄積用!E$2:E$10000, ">=1500")>0, "〇", IF(COUNTIFS(【データ】蓄積用!A$2:A$10000, AF$5, 【データ】蓄積用!C$2:C$10000, $A9, 【データ】蓄積用!Q$2:Q$10000, 1, 【データ】蓄積用!AC$2:AC$10000, ">=4.0")>0, "〇", "×"))) -> × | AG9: =IF(OR($A9="", AG$5=""), "", IF(COUNTIFS(【データ】蓄積用!A$2:A$10000, AG$5, 【データ】蓄積用!C$2:C$10000, $A9, 【データ】蓄積用!D$2:D$10000, ">=3000", 【データ】蓄積用!E$2:E$10000, ">=1500")>0, "〇", IF(COUNTIFS(【データ】蓄積用!A$2:A$10000, AG$5, 【データ】蓄積用!C$2:C$10000, $A9, 【データ】蓄積用!Q$2:Q$10000, 1, 【データ】蓄積用!AC$2:AC$10000, ">=4.0")>0, "〇", "×"))) -> × | AH9: =IF(OR($A9="", AH$5=""), "", IF(COUNTIFS(【データ】蓄積用!A$2:A$10000, AH$5, 【データ】蓄積用!C$2:C$10000, $A9, 【データ】蓄積用!D$2:D$10000, ">=3000", 【データ】蓄積用!E$2:E$10000, ">=1500")>0, "〇", IF(COUNTIFS(【データ】蓄積用!A$2:A$10000, AH$5, 【データ】蓄積用!C$2:C$10000, $A9, 【データ】蓄積用!Q$2:Q$10000, 1, 【データ】蓄積用!AC$2:AC$10000, ">=4.0")>0, "〇", "×"))) -> × | AI9: =IF(OR($A9="", AI$5=""), "", IF(COUNTIFS(【データ】蓄積用!A$2:A$10000, AI$5, 【データ】蓄積用!C$2:C$10000, $A9, 【データ】蓄積用!D$2:D$10000, ">=3000", 【データ】蓄積用!E$2:E$10000, ">=1500")>0, "〇", IF(COUNTIFS(【データ】蓄積用!A$2:A$10000, AI$5, 【データ】蓄積用!C$2:C$10000, $A9, 【データ】蓄積用!Q$2:Q$10000, 1, 【データ】蓄積用!AC$2:AC$10000, ">=4.0")>0, "〇", "×"))) -> × | AJ9: =IF(OR($A9="", AJ$5=""), "", IF(COUNTIFS(【データ】蓄積用!A$2:A$10000, AJ$5, 【データ】蓄積用!C$2:C$10000, $A9, 【データ】蓄積用!D$2:D$10000, ">=3000", 【データ】蓄積用!E$2:E$10000, ">=1500")>0, "〇", IF(COUNTIFS(【データ】蓄積用!A$2:A$10000, AJ$5, 【データ】蓄積用!C$2:C$10000, $A9, 【データ】蓄積用!Q$2:Q$10000, 1, 【データ】蓄積用!AC$2:AC$10000, ">=4.0")>0, "〇", "×"))) -> × | AK9: =IF(OR($A9="", AK$5=""), "", IF(COUNTIFS(【データ】蓄積用!A$2:A$10000, AK$5, 【データ】蓄積用!C$2:C$10000, $A9, 【データ】蓄積用!D$2:D$10000, ">=3000", 【データ】蓄積用!E$2:E$10000, ">=1500")>0, "〇", IF(COUNTIFS(【データ】蓄積用!A$2:A$10000, AK$5, 【データ】蓄積用!C$2:C$10000, $A9, 【データ】蓄積用!Q$2:Q$10000, 1, 【データ】蓄積用!AC$2:AC$10000, ">=4.0")>0, "〇", "×"))) -> × | AL9: =IF(OR($A9="", AL$5=""), "", IF(COUNTIFS(【データ】蓄積用!A$2:A$10000, AL$5, 【データ】蓄積用!C$2:C$10000, $A9, 【データ】蓄積用!D$2:D$10000, ">=3000", 【データ】蓄積用!E$2:E$10000, ">=1500")>0, "〇", IF(COUNTIFS(【データ】蓄積用!A$2:A$10000, AL$5, 【データ】蓄積用!C$2:C$10000, $A9, 【データ】蓄積用!Q$2:Q$10000, 1, 【データ】蓄積用!AC$2:AC$10000, ">=4.0")>0, "〇", "×"))) -> × | AM9: =IF(OR($A9="", AM$5=""), "", IF(COUNTIFS(【データ】蓄積用!A$2:A$10000, AM$5, 【データ】蓄積用!C$2:C$10000, $A9, 【データ】蓄積用!D$2:D$10000, ">=3000", 【データ】蓄積用!E$2:E$10000, ">=1500")>0, "〇", IF(COUNTIFS(【データ】蓄積用!A$2:A$10000, AM$5, 【データ】蓄積用!C$2:C$10000, $A9, 【データ】蓄積用!Q$2:Q$10000, 1, 【データ】蓄積用!AC$2:AC$10000, ">=4.0")>0, "〇", "×"))) -> 〇 | AN9: =IF(OR($A9="", AN$5=""), "", IF(COUNTIFS(【データ】蓄積用!A$2:A$10000, AN$5, 【データ】蓄積用!C$2:C$10000, $A9, 【データ】蓄積用!D$2:D$10000, ">=3000", 【データ】蓄積用!E$2:E$10000, ">=1500")>0, "〇", IF(COUNTIFS(【データ】蓄積用!A$2:A$10000, AN$5, 【データ】蓄積用!C$2:C$10000, $A9, 【データ】蓄積用!Q$2:Q$10000, 1, 【データ】蓄積用!AC$2:AC$10000, ">=4.0")>0, "〇", "×"))) -> × | AO9: =IF(OR($A9="", AO$5=""), "", IF(COUNTIFS(【データ】蓄積用!A$2:A$10000, AO$5, 【データ】蓄積用!C$2:C$10000, $A9, 【データ】蓄積用!D$2:D$10000, ">=3000", 【データ】蓄積用!E$2:E$10000, ">=1500")>0, "〇", IF(COUNTIFS(【データ】蓄積用!A$2:A$10000, AO$5, 【データ】蓄積用!C$2:C$10000, $A9, 【データ】蓄積用!Q$2:Q$10000, 1, 【データ】蓄積用!AC$2:AC$10000, ">=4.0")>0, "〇", "×"))) -> × | AP9: =IF(OR($A9="", AP$5=""), "", IF(COUNTIFS(【データ】蓄積用!A$2:A$10000, AP$5, 【データ】蓄積用!C$2:C$10000, $A9, 【データ】蓄積用!D$2:D$10000, ">=3000", 【データ】蓄積用!E$2:E$10000, ">=1500")>0, "〇", IF(COUNTIFS(【データ】蓄積用!A$2:A$10000, AP$5, 【データ】蓄積用!C$2:C$10000, $A9, 【データ】蓄積用!Q$2:Q$10000, 1, 【データ】蓄積用!AC$2:AC$10000, ">=4.0")>0, "〇", "×"))) -> × | AQ9: =IF(OR($A9="", AQ$5=""), "", IF(COUNTIFS(【データ】蓄積用!A$2:A$10000, AQ$5, 【データ】蓄積用!C$2:C$10000, $A9, 【データ】蓄積用!D$2:D$10000, ">=3000", 【データ】蓄積用!E$2:E$10000, ">=1500")>0, "〇", IF(COUNTIFS(【データ】蓄積用!A$2:A$10000, AQ$5, 【データ】蓄積用!C$2:C$10000, $A9, 【データ】蓄積用!Q$2:Q$10000, 1, 【データ】蓄積用!AC$2:AC$10000, ">=4.0")>0, "〇", "×"))) -> × | AR9: =IF(OR($A9="", AR$5=""), "", IF(COUNTIFS(【データ】蓄積用!A$2:A$10000, AR$5, 【データ】蓄積用!C$2:C$10000, $A9, 【データ】蓄積用!D$2:D$10000, ">=3000", 【データ】蓄積用!E$2:E$10000, ">=1500")>0, "〇", IF(COUNTIFS(【データ】蓄積用!A$2:A$10000, AR$5, 【データ】蓄積用!C$2:C$10000, $A9, 【データ】蓄積用!Q$2:Q$10000, 1, 【データ】蓄積用!AC$2:AC$10000, ">=4.0")>0, "〇", "×"))) -> × | AS9: =IF(OR($A9="", AS$5=""), "", IF(COUNTIFS(【データ】蓄積用!A$2:A$10000, AS$5, 【データ】蓄積用!C$2:C$10000, $A9, 【データ】蓄積用!D$2:D$10000, ">=3000", 【データ】蓄積用!E$2:E$10000, ">=1500")>0, "〇", IF(COUNTIFS(【データ】蓄積用!A$2:A$10000, AS$5, 【データ】蓄積用!C$2:C$10000, $A9, 【データ】蓄積用!Q$2:Q$10000, 1, 【データ】蓄積用!AC$2:AC$10000, ">=4.0")>0, "〇", "×"))) -> × | AT9: =IF(OR($A9="", AT$5=""), "", IF(COUNTIFS(【データ】蓄積用!A$2:A$10000, AT$5, 【データ】蓄積用!C$2:C$10000, $A9, 【データ】蓄積用!D$2:D$10000, ">=3000", 【データ】蓄積用!E$2:E$10000, ">=1500")>0, "〇", IF(COUNTIFS(【データ】蓄積用!A$2:A$10000, AT$5, 【データ】蓄積用!C$2:C$10000, $A9, 【データ】蓄積用!Q$2:Q$10000, 1, 【データ】蓄積用!AC$2:AC$10000, ">=4.0")>0, "〇", "×"))) -> × | AU9: =IF(OR($A9="", AU$5=""), "", IF(COUNTIFS(【データ】蓄積用!A$2:A$10000, AU$5, 【データ】蓄積用!C$2:C$10000, $A9, 【データ】蓄積用!D$2:D$10000, ">=3000", 【データ】蓄積用!E$2:E$10000, ">=1500")>0, "〇", IF(COUNTIFS(【データ】蓄積用!A$2:A$10000, AU$5, 【データ】蓄積用!C$2:C$10000, $A9, 【データ】蓄積用!Q$2:Q$10000, 1, 【データ】蓄積用!AC$2:AC$10000, ">=4.0")>0, "〇", "×"))) -> × | AV9: =IF(OR($A9="", AV$5=""), "", IF(COUNTIFS(【データ】蓄積用!A$2:A$10000, AV$5, 【データ】蓄積用!C$2:C$10000, $A9, 【データ】蓄積用!D$2:D$10000, ">=3000", 【データ】蓄積用!E$2:E$10000, ">=1500")>0, "〇", IF(COUNTIFS(【データ】蓄積用!A$2:A$10000, AV$5, 【データ】蓄積用!C$2:C$10000, $A9, 【データ】蓄積用!Q$2:Q$10000, 1, 【データ】蓄積用!AC$2:AC$10000, ">=4.0")>0, "〇", "×"))) -> × | AW9: =IF(OR($A9="", AW$5=""), "", IF(COUNTIFS(【データ】蓄積用!A$2:A$10000, AW$5, 【データ】蓄積用!C$2:C$10000, $A9, 【データ】蓄積用!D$2:D$10000, ">=3000", 【データ】蓄積用!E$2:E$10000, ">=1500")>0, "〇", IF(COUNTIFS(【データ】蓄積用!A$2:A$10000, AW$5, 【データ】蓄積用!C$2:C$10000, $A9, 【データ】蓄積用!Q$2:Q$10000, 1, 【データ】蓄積用!AC$2:AC$10000, ">=4.0")>0, "〇", "×"))) -> × | AX9: =IF(OR($A9="", AX$5=""), "", IF(COUNTIFS(【データ】蓄積用!A$2:A$10000, AX$5, 【データ】蓄積用!C$2:C$10000, $A9, 【データ】蓄積用!D$2:D$10000, ">=3000", 【データ】蓄積用!E$2:E$10000, ">=1500")>0, "〇", IF(COUNTIFS(【データ】蓄積用!A$2:A$10000, AX$5, 【データ】蓄積用!C$2:C$10000, $A9, 【データ】蓄積用!Q$2:Q$10000, 1, 【データ】蓄積用!AC$2:AC$10000, ">=4.0")>0, "〇", "×"))) -> × | AY9: =IF(OR($A9="", AY$5=""), "", IF(COUNTIFS(【データ】蓄積用!A$2:A$10000, AY$5, 【データ】蓄積用!C$2:C$10000, $A9, 【データ】蓄積用!D$2:D$10000, ">=3000", 【データ】蓄積用!E$2:E$10000, ">=1500")>0, "〇", IF(COUNTIFS(【データ】蓄積用!A$2:A$10000, AY$5, 【データ】蓄積用!C$2:C$10000, $A9, 【データ】蓄積用!Q$2:Q$10000, 1, 【データ】蓄積用!AC$2:AC$10000, ">=4.0")>0, "〇", "×")))
